Workbook

Sheet Legenda
A1: Gabarito (ground-truth)
A3: Origem | B3: Programas da CBSA na pasta ORIGINAL do repositório da base de dados (commit e22475691524ef72a92ee77f7040233e098ab1b9, ijmitch/cics-banking-sample-application-cbsa). Números de linha referem-se aos arquivos do ORIGINAL.
A4: Arquivos (SHA-256) | B4: DBCRFUN.cbl: 632917d17138331d540b05823c840eb204675ddb79ac9eac0d8d6d847982056f XFRFUN.cbl: 9c642ade5e1211b77b7c264eaea18f8cf88cb035af32ed55c66278482e51013e BNK1CRA.cbl: 061d73de30c1a3635db44b1f9dc8faebc71ea8e024fee48db499ad1ecda4ab97 BNK1TFN.cbl: 8bbc799b498a756a367ccf6dfb52d1d15579fe72332efbb86906e729edf519e2
A5: Como foi gerado | B5: Extração automática (script monta_planilha.py). Cada bloco de comentário da PROCEDURE DIVISION é pareado ao código que o segue, até o próximo comentário. O trecho exibido é limitado a 50 linhas, mas o filtro avalia o bloco inteiro. Quando o comentário vem logo após uma linha IF, ELSE, WHEN ou EVALUATE, essa linha (cabeçalho) é usada para reter o par se o corpo não tiver decisão nem falha, e aparece com o prefixo [cab.].
A6: Filtro (E4, seção 1.3) | B6: Retido: trecho com IF, EVALUATE ou WHEN, ou com tratamento de falha (ABEND, SQLCODE, HANDLE, DFHRESP, EIBRESP, EIBRCODE). O filtro é sintático: trechos de infraestrutura pura (rollback, ABEND de DB2/VSAM, storm drain) também aparecem aqui, porque contêm essas palavras-chave; a exclusão semântica é feita na revisão manual (coluna Categoria), não pelo script. Os demais (sem decisão nem falha) ficam na aba Descartados, para que o critério seja auditável.
A7: O que preencher | B7: Aba Candidatos, colunas J a M (fundo amarelo): Regra de negócio extraída, Categoria, Status e Observação, mesmas colunas usadas na revisão manual do DBCRFUN. Colunas O e P (amarelas): ID atômico (sub-regra), preenchido com a, b, c apenas quando o bloco contiver mais de uma regra, e Comentário defasado? (Sim ou Não), preenchido em toda linha revisada. Na aba Descartados, coluna I.
A8: Valores da revisão | B8: Categoria: regra de negócio, infraestrutura (excluída), interface (excluída: fluxo de teclas e telas), sem comentário próprio (excluída: regra que nenhum comentário descreve) ou a discutir (lista suspensa). Status: A validar ou Validado. Comentário defasado?: Sim = contradiz o código ou descreve algo que ele não faz; Incompleto = coerente, mas não cobre a regra toda; Não = coerente e completo. Em Descartados: Manter descartado ou Reincluir.
A9: Alertas | B9: possível código desativado: o comentário parece uma instrução COBOL comentada. comentário curto: até 3 palavras. trecho truncado: o código do par passa do limite de linhas exibidas; a coluna Linhas do código mostra o intervalo completo e a classificação considerou todo o bloco. comentários adjacentes fundidos: o bloco seguinte de comentário foi unido porque o trecho entre eles não tinha código ativo. decisão no cabeçalho anterior ao comentário: o par foi retido pela linha IF/ELSE/WHEN/EVALUATE que precede o comentário (linhas indicadas; também no código da linha anterior da planilha). comentário delega lógica (PERFORM): o trecho só chama outro parágrafo; a regra pode estar no parágrafo executado. contém GO TO: há desvio incondicional no trecho. Qtd decisões (coluna N): total de IF, EVALUATE e WHEN do bloco inteiro (+1 quando o par foi retido pelo cabeçalho); é uma contagem, não a profundidade de aninhamento. comentário menciona condição (aba Descartados): o comentário descreve uma condição, mas o trecho seguinte é só ação; a decisão pode estar antes no fonte.
A10: Limitações | B10: A triagem é heurística e não substitui a revisão dupla. Comentários de cabeçalho (antes da PROCEDURE DIVISION) não entram. Regras sem comentário associado não geram par. Linhas de depuração (indicador D) aparecem com o prefixo [D]. O tipo (Decisão, Falha, Decisão e falha) é atribuído ao bloco inteiro, não ao comentário isolado. O cabeçalho IF/ELSE que precede um comentário continua também no código do par anterior (cada linha de código pertence a um único par, exceto o cabeçalho exibido como contexto).
A12: Rascunho (assistente) | B12: Colunas J, K e M preenchidas como rascunho em fonte azul; a Observação inicia por '[Rascunho]'. Status mantido em 'A validar'. Ao conferir uma linha no fonte, ajustar o texto, trocar a fonte para preta e atualizar o Status. Linhas com a categoria 'a discutir' ou 'infraestrutura (excluída)' sem regra em J são sugestões de classificação, não decisões.
A13: Reincluídas | B13: Blocos marcados como 'Reincluir' na aba Descartados são registrados ao final da aba Candidatos, com o mesmo ID, Tipo 'Reincluído' e Estruturas 'procedural'. Na aba Resumo, deixam de ser contados como descartados e passam a contar como candidatos retidos (a soma de Decisão, Falha e Decisão e falha fica menor que Candidatos retidos pelo número de reincluídas).
A14: Revisão do orientador | B14: Feita nas reuniões semanais com o orientador; as decisões de cada reunião ficam registradas na pauta (documento 'Pontos para a reunião com o orientador — gabarito'). Registro de 16/10/2026: teclas de função como interface (excluídas); ordem de atualização das contas, gravação em PROCTRAN e falha técnica de DB2 como infraestrutura; regra afetada por defeito do código retirada e documentada (BNK1CRA-040). Critério de regra de negócio definido na reunião: é o que a área de negócio (gerente ou cliente do banco) entende; detalhe de código fica fora. Casos sem certeza sobre o comportamento são excluídos (amostra menor, com 100% de certeza). Regras que nenhum comentário descreve foram retiradas (ponto 5). Programas confirmados: DBCRFUN, XFRFUN, BNK1CRA e BNK1TFN; teste piloto com DBCRFUN e BNK1CRA.
A15: Exemplo de regra atômica | B15: Ilustrativo, não faz parte do gabarito: "Se o valor solicitado for um débito e o saldo disponível for insuficiente, a solicitação é negada." (uma condição e uma consequência por regra)
A1002: Gabarito (aba) | B1002: Gerada em 16/10/2026 por gera_gabarito.py: 46 regras atômicas, de 33 pares validados como regra de negócio. Regras numeradas na coluna 'Regra de negócio extraída' viram linhas próprias (ID do par seguido de .1, .2, ...). Pares fora do gabarito, além da infraestrutura: 14 interface (excluída) / Validado; 4 sem comentário próprio (excluída) / Validado. Recriar a aba sempre que a revisão mudar.

Sheet Resumo
A1: Programa | B1: Blocos com texto | C1: Candidatos retidos | D1: Descartados | E1: Decisão | F1: Falha | G1: Decisão e falha | H1: Com alertas | I1: Regra de negócio | J1: Infraestrutura (excluída) | K1: A discutir | L1: Validados | M1: Pendentes | N1: Defasagem avaliada (regras) | O1: Comentário defasado (Sim) | P1: Comentário incompleto | Q1: Interface (excluída) | R1: Sem comentário próprio (excluída)
A2: DBCRFUN | B2: =C2+D2 | C2: =COUNTIF(Candidatos!$B:$B,$A2) | D2: =COUNTIFS(Descartados!$B:$B,$A2,Descartados!$I:$I,"<>Reincluir") | E2: =COUNTIFS(Candidatos!$B:$B,$A2,Candidatos!$G:$G,"Decisão") | F2: =COUNTIFS(Candidatos!$B:$B,$A2,Candidatos!$G:$G,"Falha") | G2: =COUNTIFS(Candidatos!$B:$B,$A2,Candidatos!$G:$G,"Decisão e falha") | H2: =COUNTIFS(Candidatos!$B:$B,$A2,Candidatos!$I:$I,"<>") | I2: =COUNTIFS(Candidatos!$B:$B,$A2,Candidatos!$K:$K,"regra de negócio") | J2: =COUNTIFS(Candidatos!$B:$B,$A2,Candidatos!$K:$K,"infraestrutura (excluída)") | K2: =COUNTIFS(Candidatos!$B:$B,$A2,Candidatos!$K:$K,"a discutir") | L2: =COUNTIFS(Candidatos!$B:$B,$A2,Candidatos!$L:$L,"Validado") | M2: =C2-L2 | N2: =COUNTIFS(Candidatos!$B:$B,$A2,Candidatos!$K:$K,"regra de negócio",Candidatos!$P:$P,"<>") | O2: =COUNTIFS(Candidatos!$B:$B,$A2,Candidatos!$K:$K,"regra de negócio",Candidatos!$P:$P,"Sim") | P2: =COUNTIFS(Candidatos!$B:$B,$A2,Candidatos!$K:$K,"regra de negócio",Candidatos!$P:$P,"Incompleto") | Q2: =COUNTIFS(Candidatos!$B:$B,$A2,Candidatos!$K:$K,"interface (excluída)") | R2: =COUNTIFS(Candidatos!$B:$B,$A2,Candidatos!$K:$K,"sem comentário próprio (excluída)")
A3: XFRFUN | B3: =C3+D3 | C3: =COUNTIF(Candidatos!$B:$B,$A3) | D3: =COUNTIFS(Descartados!$B:$B,$A3,Descartados!$I:$I,"<>Reincluir") | E3: =COUNTIFS(Candidatos!$B:$B,$A3,Candidatos!$G:$G,"Decisão") | F3: =COUNTIFS(Candidatos!$B:$B,$A3,Candidatos!$G:$G,"Falha") | G3: =COUNTIFS(Candidatos!$B:$B,$A3,Candidatos!$G:$G,"Decisão e falha") | H3: =COUNTIFS(Candidatos!$B:$B,$A3,Candidatos!$I:$I,"<>") | I3: =COUNTIFS(Candidatos!$B:$B,$A3,Candidatos!$K:$K,"regra de negócio") | J3: =COUNTIFS(Candidatos!$B:$B,$A3,Candidatos!$K:$K,"infraestrutura (excluída)") | K3: =COUNTIFS(Candidatos!$B:$B,$A3,Candidatos!$K:$K,"a discutir") | L3: =COUNTIFS(Candidatos!$B:$B,$A3,Candidatos!$L:$L,"Validado") | M3: =C3-L3 | N3: =COUNTIFS(Candidatos!$B:$B,$A3,Candidatos!$K:$K,"regra de negócio",Candidatos!$P:$P,"<>") | O3: =COUNTIFS(Candidatos!$B:$B,$A3,Candidatos!$K:$K,"regra de negócio",Candidatos!$P:$P,"Sim") | P3: =COUNTIFS(Candidatos!$B:$B,$A3,Candidatos!$K:$K,"regra de negócio",Candidatos!$P:$P,"Incompleto") | Q3: =COUNTIFS(Candidatos!$B:$B,$A3,Candidatos!$K:$K,"interface (excluída)") | R3: =COUNTIFS(Candidatos!$B:$B,$A3,Candidatos!$K:$K,"sem comentário próprio (excluída)")
A4: BNK1CRA | B4: =C4+D4 | C4: =COUNTIF(Candidatos!$B:$B,$A4) | D4: =COUNTIFS(Descartados!$B:$B,$A4,Descartados!$I:$I,"<>Reincluir") | E4: =COUNTIFS(Candidatos!$B:$B,$A4,Candidatos!$G:$G,"Decisão") | F4: =COUNTIFS(Candidatos!$B:$B,$A4,Candidatos!$G:$G,"Falha") | G4: =COUNTIFS(Candidatos!$B:$B,$A4,Candidatos!$G:$G,"Decisão e falha") | H4: =COUNTIFS(Candidatos!$B:$B,$A4,Candidatos!$I:$I,"<>") | I4: =COUNTIFS(Candidatos!$B:$B,$A4,Candidatos!$K:$K,"regra de negócio") | J4: =COUNTIFS(Candidatos!$B:$B,$A4,Candidatos!$K:$K,"infraestrutura (excluída)") | K4: =COUNTIFS(Candidatos!$B:$B,$A4,Candidatos!$K:$K,"a discutir") | L4: =COUNTIFS(Candidatos!$B:$B,$A4,Candidatos!$L:$L,"Validado") | M4: =C4-L4 | N4: =COUNTIFS(Candidatos!$B:$B,$A4,Candidatos!$K:$K,"regra de negócio",Candidatos!$P:$P,"<>") | O4: =COUNTIFS(Candidatos!$B:$B,$A4,Candidatos!$K:$K,"regra de negócio",Candidatos!$P:$P,"Sim") | P4: =COUNTIFS(Candidatos!$B:$B,$A4,Candidatos!$K:$K,"regra de negócio",Candidatos!$P:$P,"Incompleto") | Q4: =COUNTIFS(Candidatos!$B:$B,$A4,Candidatos!$K:$K,"interface (excluída)") | R4: =COUNTIFS(Candidatos!$B:$B,$A4,Candidatos!$K:$K,"sem comentário próprio (excluída)")
A5: BNK1TFN | B5: =C5+D5 | C5: =COUNTIF(Candidatos!$B:$B,$A5) | D5: =COUNTIFS(Descartados!$B:$B,$A5,Descartados!$I:$I,"<>Reincluir") | E5: =COUNTIFS(Candidatos!$B:$B,$A5,Candidatos!$G:$G,"Decisão") | F5: =COUNTIFS(Candidatos!$B:$B,$A5,Candidatos!$G:$G,"Falha") | G5: =COUNTIFS(Candidatos!$B:$B,$A5,Candidatos!$G:$G,"Decisão e falha") | H5: =COUNTIFS(Candidatos!$B:$B,$A5,Candidatos!$I:$I,"<>") | I5: =COUNTIFS(Candidatos!$B:$B,$A5,Candidatos!$K:$K,"regra de negócio") | J5: =COUNTIFS(Candidatos!$B:$B,$A5,Candidatos!$K:$K,"infraestrutura (excluída)") | K5: =COUNTIFS(Candidatos!$B:$B,$A5,Candidatos!$K:$K,"a discutir") | L5: =COUNTIFS(Candidatos!$B:$B,$A5,Candidatos!$L:$L,"Validado") | M5: =C5-L5 | N5: =COUNTIFS(Candidatos!$B:$B,$A5,Candidatos!$K:$K,"regra de negócio",Candidatos!$P:$P,"<>") | O5: =COUNTIFS(Candidatos!$B:$B,$A5,Candidatos!$K:$K,"regra de negócio",Candidatos!$P:$P,"Sim") | P5: =COUNTIFS(Candidatos!$B:$B,$A5,Candidatos!$K:$K,"regra de negócio",Candidatos!$P:$P,"Incompleto") | Q5: =COUNTIFS(Candidatos!$B:$B,$A5,Candidatos!$K:$K,"interface (excluída)") | R5: =COUNTIFS(Candidatos!$B:$B,$A5,Candidatos!$K:$K,"sem comentário próprio (excluída)")
A6: TOTAL | B6: =SUM(B2:B5) | C6: =SUM(C2:C5) | D6: =SUM(D2:D5) | E6: =SUM(E2:E5) | F6: =SUM(F2:F5) | G6: =SUM(G2:G5) | H6: =SUM(H2:H5) | I6: =SUM(I2:I5) | ... R6: =SUM(R2:R5)
A8: Contagens por fórmula: atualizam conforme a revisão é preenchida na aba Candidatos.

Sheet Gabarito
A1: ID da regra | B1: ID do par | C1: Programa | D1: Linhas do comentário | E1: Linhas do código | F1: Regra de negócio | G1: Comentário defasado? | H1: Origem do par | I1: Observação do par
A2: DBCRFUN-005 | B2: DBCRFUN-005 | C2: DBCRFUN | D2: 276-277 | E2: 279-287 | F2: Se a conta solicitada não for encontrada (SQLCODE igual a +100), a operação é sinalizada como malsucedida com o código de falha '1'. | G2: Não | H2: Retido pelo script | I2: O código '1' tem semântica de domínio. O código '2' (SQLCODE diferente de zero e de +100) corresponde a falha técnica de DB2 e não integra a regra, pelo mesmo critério da DBCRFUN-013 (infraestrutura). O IF externo termina na DBCRFUN-006 (Descartados): PERFORM CHECK-FOR-STORM-DRAIN-DB2 e GO TO UAD999 (infraestrutura).
A3: DBCRFUN-007 | B3: DBCRFUN-007 | C3: DBCRFUN | D3: 301-304 | E3: 307 | F3: Se o valor solicitado for crédito (não negativo), a suficiência do saldo disponível não é verificada. | G3: Não | H3: Retido pelo script | I3: O código contém só a condição (COMM-AMT < 0); as consequências do débito estão na DBCRFUN-008. Não há ELSE: crédito e valor zero não entram no bloco. A checagem de MORTGAGE/LOAN reaparece após o END-IF (DBCRFUN-009).
A4: DBCRFUN-008.1 | B4: DBCRFUN-008 | C4: DBCRFUN | D4: 309-328 | E4: 316-352 | F4: Se o valor solicitado for um débito, a solicitação vier por pagamento (COMM-FACILTYPE igual a 496) e a conta for do tipo MORTGAGE ou LOAN, a solicitação é negada com o código de falha '4'. | G4: Sim | H4: Retido pelo script | I4: Comentário e código divergem: o comentário diz que todo débito exige saldo suficiente, mas o código só nega por saldo insuficiente quando COMM-FACILTYPE = 496. Saldo zero após o débito é aceito (negação só se a diferença for menor que zero). A checagem MORTGAGE/LOAN vem antes da de saldo: conta MORTGAGE sem saldo resulta em '4', não '3'. O comentário cita 'remove the record LOCK', mas não há comando de liberação de lock no trecho. Comentários adjacentes fundidos; linhas [D] ignoradas (depuração). Linha vale por duas regras.
A5: DBCRFUN-008.2 | B5: DBCRFUN-008 | C5: DBCRFUN | D5: 309-328 | E5: 316-352 | F5: Se o valor solicitado for um débito, a solicitação vier por pagamento (COMM-FACILTYPE igual a 496) e o saldo disponível após o débito for negativo, a solicitação é negada com o código de falha '3'. | G5: Sim | H5: Retido pelo script | I5: Comentário e código divergem: o comentário diz que todo débito exige saldo suficiente, mas o código só nega por saldo insuficiente quando COMM-FACILTYPE = 496. Saldo zero após o débito é aceito (negação só se a diferença for menor que zero). A checagem MORTGAGE/LOAN vem antes da de saldo: conta MORTGAGE sem saldo resulta em '4', não '3'. O comentário cita 'remove the record LOCK', mas não há comando de liberação de lock no trecho. Comentários adjacentes fundidos; linhas [D] ignoradas (depuração). Linha vale por duas regras.
A6: DBCRFUN-009 | B6: DBCRFUN-009 | C6: DBCRFUN | D6: 356-366 | E6: 368-376 | F6: Se a solicitação vier por pagamento (COMM-FACILTYPE igual a 496) e a conta for do tipo MORTGAGE ou LOAN, a solicitação é negada com o código de falha '4'. | G6: Sim | H6: Retido pelo script | I6: Mesma condição da regra 1 da DBCRFUN-008, repetida fora do bloco de débito (após o END-IF). Como o débito já sai por GO TO UAD999 na 008, esta checagem só alcança créditos na prática, embora o código não teste o sinal do valor (o comentário fala em 'Credit'). O comentário cita 'remove the record lock', sem comando correspondente. Mantida como entrada separada (critério de não fundir duplicatas); conferir fonte, linhas 356-376.
A7: DBCRFUN-018.1 | B7: DBCRFUN-018 | C7: DBCRFUN | D7: 496 | E7: 498-506 | F7: Se o valor solicitado for um débito feito por pagamento (COMM-FACILTYPE igual a 496), o tipo da transação registrada passa a 'PDR' e a descrição recebe os 14 primeiros caracteres da origem (COMM-ORIGIN). | G7: Incompleto | H7: Retido pelo script | I7: O ELSE fecha o IF COMM-AMT < 0 aberto na DBCRFUN-017; o comentário cobre apenas a regra 1. Linha vale por duas regras.
A8: DBCRFUN-018.2 | B8: DBCRFUN-018 | C8: DBCRFUN | D8: 496 | E8: 498-506 | F8: Se o valor solicitado for crédito (não negativo), a transação registrada recebe o tipo 'CRE' e a descrição 'COUNTER RECVED'. | G8: Incompleto | H8: Retido pelo script | I8: O ELSE fecha o IF COMM-AMT < 0 aberto na DBCRFUN-017; o comentário cobre apenas a regra 1. Linha vale por duas regras.
A9: DBCRFUN-019 | B9: DBCRFUN-019 | C9: DBCRFUN | D9: 509 | E9: 511-519 | F9: Se o valor solicitado for um crédito feito por pagamento (COMM-FACILTYPE igual a 496), o tipo da transação registrada passa a 'PCR' e a descrição recebe os 14 primeiros caracteres da origem (COMM-ORIGIN). | G9: Não | H9: Retido pelo script | I9: IF aninhado no ramo de crédito (ELSE da 018). O MOVE COMM-AMT TO HV-PROCTRAN-AMOUNT ao final é procedural e fica fora da regra.
A10: XFRFUN-001 | B10: XFRFUN-001 | C10: XFRFUN | D10: 286-287 | E10: 289-296 | F10: Se o valor a transferir for menor ou igual a zero, a transferência é negada e a operação é sinalizada como malsucedida com o código de falha '4'. | G10: Incompleto | H10: Retido pelo script | I10: Divergência: o comentário fala em valor negativo, mas o código testa <= ZERO, ou seja, zero também é recusado. O código '4' é traduzido na tela como 'Please supply an amount greater than zero.' (BNK1TFN-026). A consequência final (GET-ME-OUT-OF-HERE) encerra o programa; o PERFORM UPDATE-ACCOUNT-DB2 ao fim do trecho fica fora da regra.
A11: XFRFUN-003 | B11: XFRFUN-003 | C11: XFRFUN | D11: 313-314 | E11: 316-317 | F11: Se a conta de origem e a conta de destino forem a mesma (mesmo número e mesmo código de agência), a transferência não é permitida e o programa é encerrado com ABEND de código 'SAME'. | G11: Não | H11: Retido pelo script | I11: Esta linha contém só a condição. A consequência (DISPLAY 'Cannot transfer to the same account' e ABEND 'SAME') está no bloco seguinte do fonte (linhas 318-379), fundido na XFRFUN-004 pelo extrator. A mesma restrição é validada na tela em BNK1TFN-019 (contas devem ser diferentes), com mensagem ao usuário.
A12: XFRFUN-008 | B12: XFRFUN-008 | C12: XFRFUN | D12: 392 | E12: 394-398 | F12: Se a atualização da conta de origem for bem-sucedida, a conta de destino é atualizada. | G12: Não | H12: Retido pelo script | I12: Ramo em que o número da conta de origem é menor que o da conta de destino (XFRFUN-006). A ordem de atualização por número de conta foi classificada como infraestrutura na reunião com o orientador (XFRFUN-006 e 017). Estrutura espelhada na XFRFUN-019 (ordem inversa). Falhas seguem para rollback/ABEND (XFRFUN-009 a 015).
... A25: BNK1CRA-040 | B25: BNK1CRA-040 | C25: BNK1CRA | D25: 1038-1042 | E25: 1044-1064 | F25: Se o valor informado contiver caracteres diferentes de dígitos e ponto decimal, a entrada é considerada inválida e é exibida a mensagem 'Please supply a numeric amount.' | G25: Não | H25: Retido pelo script | I25: Os caracteres aceitos (dígitos 0 a 9 e '.') são os contados no INSPECT que antecede o trecho. O segundo literal é perdido por DELIMITED BY SPACES; a mensagem exibida termina em 'embedded'. Decisão da reunião com o orientador (ponto 8): a regra dos espaços embutidos foi retirada do gabarito, porque o defeito do código deixa incerto se vale a intenção do programador ou o comportamento real; fica documentada aqui: Se o valor informado contiver espaços embutidos, a entrada é considerada inválida e é exibida a mensagem 'Please supply a numeric amount without embedded'
A26: BNK1CRA-041 | B26: BNK1CRA-041 | C26: BNK1CRA | D26: 1067 | E26: 1069-1083 | F26: Se o valor informado contiver mais de um ponto decimal, a entrada é considerada inválida e é exibida a mensagem 'Use one decimal point for amount only.' | G26: Não | H26: Retido pelo script
A27: BNK1CRA-042 | B27: BNK1CRA-042 | C27: BNK1CRA | D27: 1086 | E27: 1088-1114 | F27: Se o valor informado tiver mais de duas casas decimais, a entrada é considerada inválida e é exibida a mensagem 'Only up to two decimal places are supported.' | G27: Não | H27: Retido pelo script | I27: A condição está nesta linha (dois IF aninhados); a mensagem e a consequência estão na BNK1CRA-043. Trecho de código extenso e repetitivo (INSPECT com contagem por dígito).
A28: BNK1TFN-014 | B28: BNK1TFN-014 | C28: BNK1TFN | D28: 333-334 | E28: 336-340 | F28: Se os dados informados passarem na validação (VALID-DATA), a transferência é solicitada ao programa XFRFUN (GET-ACC-DATA). | G28: Incompleto | H28: Retido pelo script | I28: O SET SEND-DATAONLY-ALARM executado em seguida é procedural e fica fora da regra.
A29: BNK1TFN-019.1 | B29: BNK1TFN-019 | C29: BNK1TFN | D29: 431 | E29: 433-467 | F29: Se o número da conta de origem informado não for numérico, a entrada é considerada inválida e é exibida a mensagem 'Please enter a FROM account no'. | G29: Não | H29: Retido pelo script | I29: Linha vale por quatro regras. A restrição de contas iguais também existe no XFRFUN-003 (ABEND 'SAME'): a tela barra antes de chegar ao programa de negócio.
A30: BNK1TFN-019.2 | B30: BNK1TFN-019 | C30: BNK1TFN | D30: 431 | E30: 433-467 | F30: Se o número da conta de destino informado não for numérico, a entrada é considerada inválida e é exibida a mensagem 'Please enter a TO account no'. | G30: Não | H30: Retido pelo script | I30: Linha vale por quatro regras. A restrição de contas iguais também existe no XFRFUN-003 (ABEND 'SAME'): a tela barra antes de chegar ao programa de negócio.
A31: BNK1TFN-019.3 | B31: BNK1TFN-019 | C31: BNK1TFN | D31: 431 | E31: 433-467 | F31: Se as contas de origem e de destino informadas forem iguais, a entrada é considerada inválida e é exibida a mensagem 'The FROM & TO account should be different'. | G31: Não | H31: Retido pelo script | I31: Linha vale por quatro regras. A restrição de contas iguais também existe no XFRFUN-003 (ABEND 'SAME'): a tela barra antes de chegar ao programa de negócio.
A32: BNK1TFN-019.4 | B32: BNK1TFN-019 | C32: BNK1TFN | D32: 431 | E32: 433-467 | F32: Se a conta de origem ou a de destino for 00000000, a entrada é considerada inválida e é exibida a mensagem 'Account no 00000000 is not valid'. | G32: Não | H32: Retido pelo script | I32: Linha vale por quatro regras. A restrição de contas iguais também existe no XFRFUN-003 (ABEND 'SAME'): a tela barra antes de chegar ao programa de negócio.
A33: BNK1TFN-026.1 | B33: BNK1TFN-026 | C33: BNK1TFN | D33: 580-581 | E33: 582-640 | F33: Se a transferência não for bem-sucedida e o código de falha for '1', é exibida a mensagem de conta de origem não encontrada e transferência não aplicada. | G33: Incompleto | H33: Retido pelo script | I33: Linha vale por quatro regras. Foram retiradas as regras do código '3' (falha técnica), do WHEN OTHER (mensagem genérica) e da checagem SUBPGM-SUCCESS NOT = 'Y' (mensagem 'unable to determine success'), por serem tratamento de erro padrão, pelo mesmo critério da DBCRFUN-005 e da BNK1CRA-025. A regra 4 vem do ELSE do segundo IF. Defeito no código: o WHEN '3' não tem GO TO GCD999 (os demais têm); o fluxo segue para o segundo IF e, como SUBPGM-SUCCESS continua 'N', a mensagem 'unexpected error' é sobrescrita por 'unable to determine success'. Ponto 8 da reunião com o orientador: o defeito do WHEN '3' afeta só a regra do código '3', já retirada; as regras restantes não dependem dele.
A34: BNK1TFN-026.2 | B34: BNK1TFN-026 | C34: BNK1TFN | D34: 580-581 | E34: 582-640 | F34: Se a transferência não for bem-sucedida e o código de falha for '2', é exibida a mensagem de conta de destino não encontrada e transferência não aplicada. | G34: Incompleto | H34: Retido pelo script | I34: Linha vale por quatro regras. Foram retiradas as regras do código '3' (falha técnica), do WHEN OTHER (mensagem genérica) e da checagem SUBPGM-SUCCESS NOT = 'Y' (mensagem 'unable to determine success'), por serem tratamento de erro padrão, pelo mesmo critério da DBCRFUN-005 e da BNK1CRA-025. A regra 4 vem do ELSE do segundo IF. Defeito no código: o WHEN '3' não tem GO TO GCD999 (os demais têm); o fluxo segue para o segundo IF e, como SUBPGM-SUCCESS continua 'N', a mensagem 'unexpected error' é sobrescrita por 'unable to determine success'. Ponto 8 da reunião com o orientador: o defeito do WHEN '3' afeta só a regra do código '3', já retirada; as regras restantes não dependem dele.
A35: BNK1TFN-026.3 | B35: BNK1TFN-026 | C35: BNK1TFN | D35: 580-581 | E35: 582-640 | F35: Se a transferência não for bem-sucedida e o código de falha for '4', é exibida a mensagem 'Please supply an amount greater than zero.' | G35: Incompleto | H35: Retido pelo script | I35: Linha vale por quatro regras. Foram retiradas as regras do código '3' (falha técnica), do WHEN OTHER (mensagem genérica) e da checagem SUBPGM-SUCCESS NOT = 'Y' (mensagem 'unable to determine success'), por serem tratamento de erro padrão, pelo mesmo critério da DBCRFUN-005 e da BNK1CRA-025. A regra 4 vem do ELSE do segundo IF. Defeito no código: o WHEN '3' não tem GO TO GCD999 (os demais têm); o fluxo segue para o segundo IF e, como SUBPGM-SUCCESS continua 'N', a mensagem 'unexpected error' é sobrescrita por 'unable to determine success'. Ponto 8 da reunião com o orientador: o defeito do WHEN '3' afeta só a regra do código '3', já retirada; as regras restantes não dependem dele.
A36: BNK1TFN-026.4 | B36: BNK1TFN-026 | C36: BNK1TFN | D36: 580-581 | E36: 582-640 | F36: Se o indicador de sucesso da transferência for 'Y', é exibida a mensagem 'Transfer successfully applied.' | G36: Incompleto | H36: Retido pelo script | I36: Linha vale por quatro regras. Foram retiradas as regras do código '3' (falha técnica), do WHEN OTHER (mensagem genérica) e da checagem SUBPGM-SUCCESS NOT = 'Y' (mensagem 'unable to determine success'), por serem tratamento de erro padrão, pelo mesmo critério da DBCRFUN-005 e da BNK1CRA-025. A regra 4 vem do ELSE do segundo IF. Defeito no código: o WHEN '3' não tem GO TO GCD999 (os demais têm); o fluxo segue para o segundo IF e, como SUBPGM-SUCCESS continua 'N', a mensagem 'unexpected error' é sobrescrita por 'unable to determine success'. Ponto 8 da reunião com o orientador: o defeito do WHEN '3' afeta só a regra do código '3', já retirada; as regras restantes não dependem dele.
A37: BNK1TFN-041 | B37: BNK1TFN-041 | C37: BNK1TFN | D37: 988-989 | E37: 991-999 | F37: Se o campo de valor estiver vazio (comprimento zero), a entrada é considerada inválida e é exibida a mensagem 'The Amount entered must be numeric.' | G37: Sim | H37: Retido pelo script | I37: O comentário pergunta 'Is it greater than 0?', mas o teste é de comprimento do campo (AMTL = ZERO). O trecho abre o IF AMTI IS NUMERIC, cuja consequência está na BNK1TFN-042.
A38: BNK1TFN-042 | B38: BNK1TFN-042 | C38: BNK1TFN | D38: 1001 | E38: 1003-1021 | F38: Se o valor informado for numérico e menor ou igual a zero, a entrada é considerada inválida e é exibida a mensagem 'Please supply a positive amount.' | G38: Não | H38: Retido pelo script | I38: Aplica-se só a valores inteiros (IS NUMERIC); valores com ponto decimal seguem o fluxo das BNK1TFN-043 a 048. Se o valor for numérico e maior que zero, a entrada é aceita; por ser o complemento da regra, a aceitação fica fora do gabarito, como no BNK1CRA.
... A47: XFRFUN-051 | B47: XFRFUN-051 | C47: XFRFUN | D47: 1354-1355 | E47: 1357-1360 | F47: Se a leitura da conta de destino for bem-sucedida, o valor da transferência é somado ao saldo disponível e ao saldo atual da conta de destino. | G47: Não | H47: Reincluído | I47: Reincluída da aba Descartados (motivo do descarte: procedural, sem decisão nem tratamento de falha). O comentário fala em 'SELECT bem-sucedido', mas o código não contém IF: a condição é implícita, pois a falha anterior termina em ABEND 'RUF2' (linhas 1345-1347). Regra de cálculo; o UPDATE seguinte (linhas 1362-1378) é acesso a dados e fica fora do gabarito. O trecho exibido contém só o cálculo.

Sheet Candidatos
A1: ID | B1: Programa | C1: Linhas do comentário | D1: Linhas do código | E1: Comentário | F1: Trecho de código | G1: Tipo | H1: Estruturas | I1: Alertas | J1: Regra de negócio extraída | K1: Categoria | L1: Status | M1: Observação | N1: Qtd decisões | O1: ID atômico (sub-regra) | P1: Comentário defasado?
A2: DBCRFUN-001 | B2: DBCRFUN | C2: 205 | D2: 207-212 | E2: Set up some Abend handling | F2: EXEC CICS HANDLE ABEND LABEL(ABEND-HANDLING) END-EXEC. MOVE SORTCODE TO COMM-SORTC. MOVE SORTCODE TO DESIRED-SORT-CODE. | G2: Falha | H2: falha | K2: infraestrutura (excluída) | L2: Validado | M2: Configuração do tratamento de ABEND (HANDLE ABEND) e cópia do código da agência (SORTCODE), sem decisão de negócio. | N2: 0
A3: DBCRFUN-005 | B3: DBCRFUN | C3: 276-277 | D3: 279-287 | E3: Check that select was successful. If it wasn't then deal with it | F3: IF SQLCODE NOT = 0 MOVE 'N' TO COMM-SUCCESS IF SQLCODE = +100 MOVE '1' TO COMM-FAIL-CODE ELSE MOVE '2' TO COMM-FAIL-CODE END-IF | G3: Decisão e falha | H3: IF, falha | J3: Se a conta solicitada não for encontrada (SQLCODE igual a +100), a operação é sinalizada como malsucedida com o código de falha '1'. | K3: regra de negócio | L3: Validado | M3: O código '1' tem semântica de domínio. O código '2' (SQLCODE diferente de zero e de +100) corresponde a falha técnica de DB2 e não integra a regra, pelo mesmo critério da DBCRFUN-013 (infraestrutura). O IF externo termina na DBCRFUN-006 (Descartados): PERFORM CHECK-FOR-STORM-DRAIN-DB2 e GO TO UAD999 (infraestrutura). | N3: 2 | P3: Não
A4: DBCRFUN-007 | B4: DBCRFUN | C4: 301-304 | D4: 307 | E4: Is the amount being requested a debit or a credit? If it is a CREDIT (+) then we don't need to ensure that the available balance has sufficient funds, because this is money coming in. | F4: IF COMM-AMT < 0 | G4: Decisão | H4: IF | J4: Se o valor solicitado for crédito (não negativo), a suficiência do saldo disponível não é verificada. | K4: regra de negócio | L4: Validado | M4: O código contém só a condição (COMM-AMT < 0); as consequências do débito estão na DBCRFUN-008. Não há ELSE: crédito e valor zero não entram no bloco. A checagem de MORTGAGE/LOAN reaparece após o END-IF (DBCRFUN-009). | N4: 1 | P4: Não
A5: DBCRFUN-008 | B5: DBCRFUN | C5: 309-328 | D5: 316-352 | E5: The amount being requested is a DEBIT/Payment (-) so we do need to check that the available balance is sufficient to cover the amount being asked for. If there are NOT sufficient funds the request is denied so remove the record LOCK and and finish. Check to see whether the Payment is being requested from a MORTGAGE or LOAN account. We only make this check for PAYMENTs (we don't make this check for requests via the Teller). How do we know it is a PAYMENT as opposed to a Teller, this is determined by the COMM-FACILTYPE(496 = NONE) If it is a PAYMENT being requested from a MORTGAGE or LOAN account then set an appropriate fail code (4) and finish up. | F5: [D] DISPLAY 'COMM-AMT IS negative' IF (HV-ACCOUNT-ACC-TYPE = 'MORTGAGE' AND COMM-FACILTYPE = 496) OR (HV-ACCOUNT-ACC-TYPE = 'LOAN ' AND COMM-FACILTYPE = 496) MOVE 'N' TO COMM-SUCCESS MOVE '4' TO COMM-FAIL-CODE GO TO UAD999 END-IF MOVE 0 TO WS-DIFFERENCE COMPUTE WS-DIFFERENCE = HV-ACCOUNT-AVAIL-BAL + COMM-AMT IF WS-DIFFERENCE < 0 AND COMM-FACILTYPE = 496 [D] DISPLAY 'insufficient funds!' MOVE 'N' TO COMM-SUCCESS MOVE '3' TO COMM-FAIL-CODE GO TO UAD999 END-IF END-IF. | G5: Decisão | H5: IF | I5: comentários adjacentes fundidos; contém GO TO (desvio incondicional) | J5: 1. Se o valor solicitado for um débito, a solicitação vier por pagamento (COMM-FACILTYPE igual a 496) e a conta for do tipo MORTGAGE ou LOAN, a solicitação é negada com o código de falha '4'. 2. Se o valor solicitado for um débito, a solicitação vier por pagamento (COMM-FACILTYPE igual a 496) e o saldo disponível após o débito for negativo, a solicitação é negada com o código de falha '3'. | K5: regra de negócio | L5: Validado | M5: Comentário e código divergem: o comentário diz que todo débito exige saldo suficiente, mas o código só nega por saldo insuficiente quando COMM-FACILTYPE = 496. Saldo zero após o débito é aceito (negação só se a diferença for menor que zero). A checagem MORTGAGE/LOAN vem antes da de saldo: conta MORTGAGE sem saldo resulta em '4', não '3'. O comentário cita 'remove the record LOCK', mas não há comando de liberação de lock no trecho. Comentários adjacentes fundidos; linhas [D] ignoradas (depuração). Linha vale por duas regras. | N5: 2 | P5: Sim
A6: DBCRFUN-009 | B6: DBCRFUN | C6: 356-366 | D6: 368-376 | E6: Check to see whether a Credit is being requested from a MORTGAGE or LOAN account. We only make this check for requests via the PAYMENT link (we don't make this check for requests via the Teller). How do we know it is a PAYMENT as opposed to a Teller, this is determined by the COMM-FACILTYPE(496 = NONE) If it is a PAYMENT credit being requested from a MORTGAGE or LOAN account then set an appropriate fail code (4), remove the record lock and finish up. | F6: IF (HV-ACCOUNT-ACC-TYPE = 'MORTGAGE' AND COMM-FACILTYPE = 496) OR (HV-ACCOUNT-ACC-TYPE = 'LOAN ' AND COMM-FACILTYPE = 496) MOVE 'N' TO COMM-SUCCESS MOVE '4' TO COMM-FAIL-CODE GO TO UAD999 END-IF. | G6: Decisão | H6: IF | I6: contém GO TO (desvio incondicional) | J6: Se a solicitação vier por pagamento (COMM-FACILTYPE igual a 496) e a conta for do tipo MORTGAGE ou LOAN, a solicitação é negada com o código de falha '4'. | K6: regra de negócio | L6: Validado | M6: Mesma condição da regra 1 da DBCRFUN-008, repetida fora do bloco de débito (após o END-IF). Como o débito já sai por GO TO UAD999 na 008, esta checagem só alcança créditos na prática, embora o código não teste o sinal do valor (o comentário fala em 'Credit'). O comentário cita 'remove the record lock', sem comando correspondente. Mantida como entrada separada (critério de não fundir duplicatas); conferir fonte, linhas 356-376. | N6: 1 | P6: Sim
A7: DBCRFUN-012 | B7: DBCRFUN | C7: 411-412 | D7: 414-419 | E7: If the rewrite was successful then we need to pass back the amended available balance and actual balance. | F7: MOVE SQLCODE TO SQLCODE-DISPLAY. MOVE HV-ACCOUNT-AVAIL-BAL TO COMM-AV-BAL. MOVE HV-ACCOUNT-ACTUAL-BAL TO COMM-ACT-BAL. | G7: Falha | H7: falha | K7: infraestrutura (excluída) | L7: Validado | M7: Sem estrutura de decisão (retido por conter 'SQLCODE'). O comentário diz 'if the rewrite was successful', mas os MOVE de saldos ocorrem sem condição, antes do IF SQLCODE NOT = 0 (DBCRFUN-013): os saldos são devolvidos mesmo se a atualização falhar. | N7: 0
A8: DBCRFUN-013 | B8: DBCRFUN | C8: 422-423 | D8: 425-427 | E8: If the RESP CODE was NOT OK then we need to set flags accordingly | F8: IF SQLCODE NOT = 0 MOVE 'N' TO COMM-SUCCESS MOVE '2' TO COMM-FAIL-CODE | G8: Decisão e falha | H8: IF, falha | K8: infraestrutura (excluída) | L8: Validado | M8: Falha técnica de DB2 na atualização, excluída como infraestrutura (mesmo critério aplicado ao código '2' da DBCRFUN-005). O código '2' chega ao usuário como 'unexpected error' (BNK1CRA-025). O trecho termina antes do tratamento de storm drain (DBCRFUN-014, Descartados). | N8: 1
A9: DBCRFUN-017 | B9: DBCRFUN | C9: 473 | D9: 475-493 | E9: Populate the current time and date | F9: EXEC CICS ASKTIME ABSTIME(WS-U-TIME) END-EXEC. EXEC CICS FORMATTIME ABSTIME(WS-U-TIME) DDMMYYYY(WS-ORIG-DATE) TIME(HV-PROCTRAN-TIME) DATESEP('.') END-EXEC. MOVE WS-ORIG-DATE TO WS-ORIG-DATE-GRP-X. MOVE WS-ORIG-DATE-GRP-X TO HV-PROCTRAN-DATE. MOVE SPACES TO HV-PROCTRAN-DESC. IF COMM-AMT < 0 MOVE 'DEB' TO HV-PROCTRAN-TYPE MOVE 'COUNTER WTHDRW' TO HV-PROCTRAN-DESC | G9: Decisão | H9: IF | K9: sem comentário próprio (excluída) | L9: Validado | M9: Decisão do ponto 5 da pauta: a regra deste trecho não é descrita por nenhum comentário (caiu neste par porque o extrator vai até o próximo comentário) e foi retirada do gabarito. Regra redigida antes da decisão: Se o valor solicitado for negativo (débito), a transação registrada recebe o tipo 'DEB' e a descrição 'COUNTER WTHDRW'. O trecho inclui ASKTIME/FORMATTIME (data e hora da transação; procedural, fora da regra). O tipo 'DEB' é sobrescrito por 'PDR' quando a solicitação vem por pagamento (DBCRFUN-018). O ELSE de crédito ('CRE') também está na 018. A condição COMM-AMT < 0 repete a da DBCRFUN-007. | N9: 1
A10: DBCRFUN-018 | B10: DBCRFUN | C10: 496 | D10: 498-506 | E10: If it is a debit from a PAYMENT | F10: IF COMM-FACILTYPE = 496 MOVE 'PDR' TO HV-PROCTRAN-TYPE MOVE COMM-ORIGIN(1:14) TO HV-PROCTRAN-DESC END-IF ELSE MOVE 'CRE' TO HV-PROCTRAN-TYPE MOVE 'COUNTER RECVED' TO HV-PROCTRAN-DESC | G10: Decisão | H10: IF | J10: 1. Se o valor solicitado for um débito feito por pagamento (COMM-FACILTYPE igual a 496), o tipo da transação registrada passa a 'PDR' e a descrição recebe os 14 primeiros caracteres da origem (COMM-ORIGIN). 2. Se o valor solicitado for crédito (não negativo), a transação registrada recebe o tipo 'CRE' e a descrição 'COUNTER RECVED'. | K10: regra de negócio | L10: Validado | M10: O ELSE fecha o IF COMM-AMT < 0 aberto na DBCRFUN-017; o comentário cobre apenas a regra 1. Linha vale por duas regras. | N10: 1 | P10: Incompleto
A11: DBCRFUN-019 | B11: DBCRFUN | C11: 509 | D11: 511-519 | E11: If it is a credit from a PAYMENT | F11: IF COMM-FACILTYPE = 496 MOVE 'PCR' TO HV-PROCTRAN-TYPE MOVE COMM-ORIGIN(1:14) TO HV-PROCTRAN-DESC END-IF END-IF. MOVE COMM-AMT TO HV-PROCTRAN-AMOUNT. | G11: Decisão | H11: IF | J11: Se o valor solicitado for um crédito feito por pagamento (COMM-FACILTYPE igual a 496), o tipo da transação registrada passa a 'PCR' e a descrição recebe os 14 primeiros caracteres da origem (COMM-ORIGIN). | K11: regra de negócio | L11: Validado | M11: IF aninhado no ramo de crédito (ELSE da 018). O MOVE COMM-AMT TO HV-PROCTRAN-AMOUNT ao final é procedural e fica fora da regra. | N11: 1 | P11: Não
A12: DBCRFUN-021 | B12: DBCRFUN | C12: 552 | D12: 554-559 | E12: Check the SQLCODE | F12: IF SQLCODE NOT = 0 MOVE SQLCODE TO SQLCODE-DISPLAY DISPLAY 'UNABLE TO WRITE TO PROCTRAN DB2 DATASTORE' ' SQLCODE=' SQLCODE-DISPLAY 'WITH THE FOLLOWING DATA:' HOST-PROCTRAN-ROW | G12: Decisão e falha | H12: IF, falha | I12: comentário curto | K12: infraestrutura (excluída) | L12: Validado | M12: Falha na gravação em PROCTRAN (DB2): exibe diagnóstico; o rollback (022) e o ABEND (023) completam o tratamento. Falha técnica, fora do escopo pelo critério de infraestrutura. O efeito (operação desfeita se o registro falhar) é regra de consistência. | N12: 1
A13: DBCRFUN-022 | B13: DBCRFUN | C13: 561-562 | D13: 564-569 | E13: You need to issue a ROLLBACK to get rid of the updated ACCOUNT record | F13: EXEC CICS SYNCPOINT ROLLBACK RESP(WS-CICS-RESP) RESP2(WS-CICS-RESP2) END-EXEC IF WS-CICS-RESP NOT = DFHRESP(NORMAL) | G13: Decisão e falha | H13: IF, falha | K13: infraestrutura (excluída) | L13: Validado | M13: Rollback da atualização da conta (SYNCPOINT ROLLBACK) e verificação do RESP; infraestrutura transacional. | N13: 1
A14: DBCRFUN-023 | B14: DBCRFUN | C14: 571-574 | D14: 576-578 | E14: Preserve the RESP and RESP2, then set up the standard ABEND info before getting the applid, date/time etc. and linking to the Abend Handler program. | F14: INITIALIZE ABNDINFO-REC MOVE EIBRESP TO ABND-RESPCODE MOVE EIBRESP2 TO ABND-RESP2CODE | G14: Falha | H14: falha | K14: infraestrutura (excluída) | L14: Validado | M14: Montagem padrão das informações de ABEND (INITIALIZE ABNDINFO-REC; MOVE EIBRESP/EIBRESP2); tratamento técnico sem semântica bancária. | N14: 0
A15: DBCRFUN-024 | B15: DBCRFUN | C15: 580 | D15: 582-637 | E15: Get supplemental information | F15: EXEC CICS ASSIGN APPLID(ABND-APPLID) END-EXEC MOVE EIBTASKN TO ABND-TASKNO-KEY MOVE EIBTRNID TO ABND-TRANID PERFORM POPULATE-TIME-DATE MOVE WS-ORIG-DATE TO ABND-DATE STRING WS-TIME-NOW-GRP-HH DELIMITED BY SIZE, ':' DELIMITED BY SIZE, WS-TIME-NOW-GRP-MM DELIMITED BY SIZE, ':' DELIMITED BY SIZE, WS-TIME-NOW-GRP-MM DELIMITED BY SIZE INTO ABND-TIME END-STRING MOVE WS-U-TIME TO ABND-UTIME-KEY MOVE 'HROL' TO ABND-CODE EXEC CICS ASSIGN PROGRAM(ABND-PROGRAM) END-EXEC MOVE ZEROS TO ABND-SQLCODE STRING 'WTPD010 - COULD NOT ROLL BACK, POSSIBLE DATA' DELIMITED BY SIZE, 'INTEGRITY ISSUE BETWEEN ACCOUNT AND PROCTRAN ' DELIMITED BY SIZE, 'FOR ROW:' DELIMITED BY SIZE, HOST-PROCTRAN-ROW DELIMITED BY SIZE, 'EIBRESP=' DELIMITED BY SIZE, ABND-RESPCODE DELIMITED BY SIZE, ' RESP2=' DELIMITED BY SIZE, ABND-RESP2CODE DELIMITED BY SIZE INTO ABND-FREEFORM END-STRING EXEC CICS LINK PROGRAM(WS-ABEND-PGM) COMMAREA(ABNDINFO-REC) END-EXEC DISPLAY ' COULD NOT ROLL BACK, POSSIBLE DATA ' 'INTEGRITY ISSUE BETWEEN ACCOUNT AND PROCTRAN ' 'FOR ROW:' HOST-PROCTRAN-ROW 'RESP CODE=' WS-CICS-RESP ' RESP2 CODE=' WS-CICS-RESP2 EXEC CICS ABEND ABCODE ('HROL') CANCEL END-EXEC END-IF MOVE 'N' TO COMM-SUCCESS MOVE '02' TO COMM-FAIL-CODE | G15: Falha | H15: falha | I15: comentário curto | K15: infraestrutura (excluída) | L15: Validado | M15: Coleta de informações complementares de ABEND (PERFORM POPULATE-TIME-DATE, LINK ao tratador de ABEND, ABEND); tratamento técnico sem semântica bancária. Estava como 'Manter descartado' na planilha anterior; o script agora o retém por conter ABEND (antes o trecho era cortado antes dele). | N15: 0
A16: DBCRFUN-026 | B16: DBCRFUN | C16: 647 | D16: 644; 649-669 | E16: If the WRITE to PROCTRAN worked then it was a success | F16: [cab.] ELSE MOVE 'Y' TO COMM-SUCCESS MOVE '0' TO COMM-FAIL-CODE END-IF. WTPD999. EXIT. GET-ME-OUT-OF-HERE SECTION. GMOOH010. EXEC CICS RETURN END-EXEC. GOBACK. GMOOH999. EXIT. CHECK-FOR-STORM-DRAIN-DB2 SECTION. CFSDD010. | G16: Decisão | H16: ELSE (cabeçalho) | I16: decisão no cabeçalho anterior ao comentário (linha 644) | K16: infraestrutura (excluída) | L16: Validado | M16: Decisão posterior à reunião, pela mesma lógica do XFRFUN-032 (ponto 3): a sinalização de sucesso após a gravação em PROCTRAN é detalhe de código. Critério definido com o orientador: regra de negócio é o que a área de negócio (gerente ou cliente do banco) entende; detalhe de código fica fora. Regra redigida antes da decisão: Se a gravação em PROCTRAN for bem-sucedida, a operação é sinalizada como bem-sucedida (COMM-SUCCESS igual a 'Y') com o código de falha '0'. Reincluída da aba Descartados (motivo do descarte: procedural, sem decisão nem tratamento de falha). Ramo ELSE do IF SQLCODE NOT = 0 da gravação em PROCTRAN (ramo de falha na DBCRFUN-021, classificado como infraestrutura). É o único ponto em que COMM-SUCCESS recebe 'Y': o sucesso da operação depende da gravação do registro. O trecho extraído inclui as seções seguintes (GET-ME-OUT-OF-HERE e CHECK-FOR-STORM-DRAIN-DB2), por corte do extrator; ficam fora da regra. | N16: 1
A17: DBCRFUN-027 | B17: DBCRFUN | C17: 671-672 | D17: 675-695 | E17: Check if the Sqclode that is returned one that will trigger Storm Drain is active in Workload | F17: EVALUATE SQLCODE WHEN 923 MOVE 'DB2 Connection lost ' TO STORM-DRAIN-CONDITION WHEN OTHER MOVE 'Not Storm Drain ' TO STORM-DRAIN-CONDITION END-EVALUATE. IF STORM-DRAIN-CONDITION NOT EQUAL 'Not Storm Drain ' DISPLAY 'DBCRFUN: Check-For-Storm-Drain-DB2: Storm ' 'Drain condition (' STORM-DRAIN-CONDITION ') ' 'has been met (' SQLCODE-DISPLAY ').' ELSE CONTINUE END-IF. CFSDD999. EXIT. | G17: Decisão e falha | H17: IF, EVALUATE, WHEN, falha | K17: infraestrutura (excluída) | L17: Validado | M17: Verificação de condição de storm drain do DB2 (EVALUATE SQLCODE, WHEN 923); infraestrutura. | N17: 4
A18: DBCRFUN-029 | B18: DBCRFUN | C18: 708-713 | D18: 716 | E18: Evaluate the Abend code that is returned - For DB2 AD2Z ... provide some diagnostics - For VSAM RLS abends: AFCR, AFCS and AFCT record the Abend as happening but do not abend ... leave this to CPSM WLM "Storm drain" (Abend probability) to handle If not a "storm drain" ... take the abend afterwards | F18: EVALUATE MY-ABEND-CODE | G18: Decisão | H18: EVALUATE | K18: infraestrutura (excluída) | L18: Validado | M18: Avaliação do código de ABEND (EVALUATE MY-ABEND-CODE) para diagnóstico e storm drain de DB2 e VSAM; infraestrutura. | N18: 1
A19: DBCRFUN-030 | B19: DBCRFUN | C19: 718 | D19: 720-735 | E19: DB2 AD2Z abend | F19: WHEN 'AD2Z' MOVE SQLCODE TO SQLCODE-DISPLAY DISPLAY 'DB2 DEADLOCK DETECTED IN DBCRFUN, SQLCODE=' SQLCODE-DISPLAY DISPLAY 'DB2 DEADLOCK FOR ACCOUNT ' HV-ACCOUNT-ACC-NO DISPLAY 'SQLSTATE=' SQLSTATE ',SQLERRMC=' SQLERRMC(1:SQLERRML) ',SQLERRD(1)=' SQLERRD(1) ',SQLERRD(2)=' SQLERRD(2) ',SQLERRD(3)=' SQLERRD(3) ',SQLERRD(4)=' SQLERRD(4) ',SQLERRD(5)=' SQLERRD(5) ',SQLERRD(6)=' SQLERRD(6) | G19: Decisão e falha | H19: WHEN, falha | I19: comentário curto | K19: infraestrutura (excluída) | L19: Validado | M19: Tratamento do ABEND AD2Z (deadlock DB2) com exibição de diagnósticos; infraestrutura. | N19: 1
A20: DBCRFUN-031 | B20: DBCRFUN | C20: 738-740 | D20: 742-756 | E20: VSAM RLS abends, subject to CPSM WLM Storm Drain check if handled (as here) and Workload Abend Thresholds are set. | F20: WHEN 'AFCR' WHEN 'AFCS' WHEN 'AFCT' MOVE 'Y' TO WS-STORM-DRAIN DISPLAY 'DBCRFUN: Check-For-Storm-Drain-VSAM: Storm ' 'Drain condition (Abend ' MY-ABEND-CODE ') ' 'has been met.' EXEC CICS SYNCPOINT ROLLBACK RESP(WS-CICS-RESP) RESP2(WS-CICS-RESP2) END-EXEC IF WS-CICS-RESP NOT = DFHRESP(NORMAL) | G20: Decisão e falha | H20: IF, WHEN, falha | K20: infraestrutura (excluída) | L20: Validado | M20: Tratamento dos ABEND AFCR, AFCS e AFCT (VSAM RLS, storm drain) com rollback; infraestrutura. | N20: 4
A21: DBCRFUN-032 | B21: DBCRFUN | C21: 758-761 | D21: 763-765 | E21: Preserve the RESP and RESP2, then set up the standard ABEND info before getting the applid, date/time etc. and linking to the Abend Handler program. | F21: INITIALIZE ABNDINFO-REC MOVE EIBRESP TO ABND-RESPCODE MOVE EIBRESP2 TO ABND-RESP2CODE | G21: Falha | H21: falha | K21: infraestrutura (excluída) | L21: Validado | M21: Montagem padrão das informações de ABEND (INITIALIZE ABNDINFO-REC; MOVE EIBRESP/EIBRESP2); tratamento técnico sem semântica bancária. | N21: 0
A22: DBCRFUN-033 | B22: DBCRFUN | C22: 767 | D22: 769-861 | E22: Get supplemental information | F22: EXEC CICS ASSIGN APPLID(ABND-APPLID) END-EXEC MOVE EIBTASKN TO ABND-TASKNO-KEY MOVE EIBTRNID TO ABND-TRANID PERFORM POPULATE-TIME-DATE MOVE WS-ORIG-DATE TO ABND-DATE STRING WS-TIME-NOW-GRP-HH DELIMITED BY SIZE, ':' DELIMITED BY SIZE, WS-TIME-NOW-GRP-MM DELIMITED BY SIZE, ':' DELIMITED BY SIZE, WS-TIME-NOW-GRP-MM DELIMITED BY SIZE INTO ABND-TIME END-STRING MOVE WS-U-TIME TO ABND-UTIME-KEY MOVE 'HROL' TO ABND-CODE EXEC CICS ASSIGN PROGRAM(ABND-PROGRAM) END-EXEC MOVE ZEROS TO ABND-SQLCODE STRING 'AH010 - Unable to perform Synpoint ' DELIMITED BY SIZE, 'Rollback.' DELIMITED BY SIZE, ' Possible Integrity issue following VSAM RLS ' DELIMITED BY SIZE, 'abend.' DELIMITED BY SIZE, 'EIBRESP=' DELIMITED BY SIZE, ABND-RESPCODE DELIMITED BY SIZE, ' RESP2=' DELIMITED BY SIZE, ABND-RESP2CODE DELIMITED BY SIZE INTO ABND-FREEFORM END-STRING EXEC CICS LINK PROGRAM(WS-ABEND-PGM) COMMAREA(ABNDINFO-REC) END-EXEC DISPLAY 'DBCRFUN: Unable to perform Synpoint ' 'Rollback.' ' Possible Integrity issue following VSAM RLS' ' abend' ' RESP CODE=' WS-CICS-RESP ' RESP2 CODE=' WS-CICS-RESP2 EXEC CICS ABEND ABCODE ('HROL') CANCEL END-EXEC END-IF MOVE 'N' TO COMM-SUCCESS MOVE '2' TO COMM-FAIL-CODE EXEC CICS RETURN END-EXEC END-EVALUATE. IF WS-STORM-DRAIN = 'N' | G22: Decisão e falha | H22: IF, falha | I22: comentário curto; trecho truncado (exibidas 50 de 71 linhas) | K22: infraestrutura (excluída) | L22: Validado | M22: Coleta de informações complementares de ABEND (PERFORM POPULATE-TIME-DATE, LINK ao tratador de ABEND, ABEND); tratamento técnico sem semântica bancária. Inclui a verificação de storm drain (IF WS-STORM-DRAIN = 'N' seguido de ABEND), que você definiu como infraestrutura. Exibidas 50 de 71 linhas; final do trecho conferido no fonte (linhas 769-861): tratamento de ABEND, storm drain e rotina de data e hora, sem regra de negócio. Estava como 'Manter descartado' na planilha anterior. | N22: 1
A23: XFRFUN-001 | B23: XFRFUN | C23: 286-287 | D23: 289-296 | E23: If the amount being transferred is negative, then flag this as a failure and finish. | F23: IF COMM-AMT <= ZERO MOVE 'N' TO COMM-SUCCESS MOVE '4' TO COMM-FAIL-CODE PERFORM GET-ME-OUT-OF-HERE END-IF. PERFORM UPDATE-ACCOUNT-DB2 | G23: Decisão | H23: IF | J23: Se o valor a transferir for menor ou igual a zero, a transferência é negada e a operação é sinalizada como malsucedida com o código de falha '4'. | K23: regra de negócio | L23: Validado | M23: Divergência: o comentário fala em valor negativo, mas o código testa <= ZERO, ou seja, zero também é recusado. O código '4' é traduzido na tela como 'Please supply an amount greater than zero.' (BNK1TFN-026). A consequência final (GET-ME-OUT-OF-HERE) encerra o programa; o PERFORM UPDATE-ACCOUNT-DB2 ao fim do trecho fica fora da regra. | N23: 1 | P23: Incompleto
A24: XFRFUN-003 | B24: XFRFUN | C24: 313-314 | D24: 316-317 | E24: Are we trying to transfer from and to the same account? We don't allow that. | F24: IF COMM-FACCNO = COMM-TACCNO AND COMM-FSCODE = COMM-TSCODE | G24: Decisão | H24: IF | J24: Se a conta de origem e a conta de destino forem a mesma (mesmo número e mesmo código de agência), a transferência não é permitida e o programa é encerrado com ABEND de código 'SAME'. | K24: regra de negócio | L24: Validado | M24: Esta linha contém só a condição. A consequência (DISPLAY 'Cannot transfer to the same account' e ABEND 'SAME') está no bloco seguinte do fonte (linhas 318-379), fundido na XFRFUN-004 pelo extrator. A mesma restrição é validada na tela em BNK1TFN-019 (contas devem ser diferentes), com mensagem ao usuário. | N24: 1 | P24: Não
A25: XFRFUN-004 | B25: XFRFUN | C25: 319-322 | D25: 324-326 | E25: Preserve the RESP and RESP2, then set up the standard ABEND info before getting the applid, date/time etc. and linking to the Abend Handler program. | F25: INITIALIZE ABNDINFO-REC MOVE EIBRESP TO ABND-RESPCODE MOVE EIBRESP2 TO ABND-RESP2CODE | G25: Falha | H25: falha | K25: infraestrutura (excluída) | L25: Validado | M25: Montagem de ABEND que compõe a consequência do IF de mesma conta (XFRFUN-003); a regra de negócio está registrada na 003. Montagem padrão das informações de ABEND (INITIALIZE ABNDINFO-REC; MOVE EIBRESP/EIBRESP2); tratamento técnico sem semântica bancária. | N25: 0
A26: XFRFUN-005 | B26: XFRFUN | C26: 328 | D26: 330-378 | E26: Get supplemental information | F26: EXEC CICS ASSIGN APPLID(ABND-APPLID) END-EXEC MOVE EIBTASKN TO ABND-TASKNO-KEY MOVE EIBTRNID TO ABND-TRANID PERFORM POPULATE-TIME-DATE MOVE WS-ORIG-DATE TO ABND-DATE STRING WS-TIME-NOW-GRP-HH DELIMITED BY SIZE, ':' DELIMITED BY SIZE, WS-TIME-NOW-GRP-MM DELIMITED BY SIZE, ':' DELIMITED BY SIZE, WS-TIME-NOW-GRP-MM DELIMITED BY SIZE INTO ABND-TIME END-STRING MOVE WS-U-TIME TO ABND-UTIME-KEY MOVE 'SAME' TO ABND-CODE EXEC CICS ASSIGN PROGRAM(ABND-PROGRAM) END-EXEC MOVE ZEROS TO ABND-SQLCODE STRING 'UAD010 - Cannot transfer to the same account ' DELIMITED BY SIZE, ' EIBRESP=' DELIMITED BY SIZE, ABND-RESPCODE DELIMITED BY SIZE, ' RESP2=' DELIMITED BY SIZE, ABND-RESP2CODE DELIMITED BY SIZE INTO ABND-FREEFORM END-STRING EXEC CICS LINK PROGRAM(WS-ABEND-PGM) COMMAREA(ABNDINFO-REC) END-EXEC DISPLAY 'Cannot transfer to the same account' EXEC CICS ABEND ABCODE('SAME') NODUMP CANCEL END-EXEC END-IF. IF COMM-FACCNO < COMM-TACCNO | G26: Decisão e falha | H26: IF, falha | I26: comentário curto | K26: infraestrutura (excluída) | L26: Validado | M26: Coleta de informações complementares de ABEND (PERFORM POPULATE-TIME-DATE, LINK ao tratador de ABEND, ABEND); tratamento técnico sem semântica bancária. O IF da linha 378, no fim do trecho, é o cabeçalho da regra de ordem de atualização (XFRFUN-006); o tipo 'Decisão e falha' vem dele. | N26: 1
A27: XFRFUN-006 | B27: XFRFUN | C27: 380-381 | D27: 378; 383-384 | E27: If the FROM account number is less than the TO account number | F27: [cab.] IF COMM-FACCNO < COMM-TACCNO MOVE COMM-FACCNO TO DESIRED-ACC-NO MOVE COMM-FSCODE TO DESIRED-SORT-CODE | G27: Decisão | H27: IF (cabeçalho) | I27: decisão no cabeçalho anterior ao comentário (linha 378) | K27: infraestrutura (excluída) | L27: Validado | M27: Decisão da reunião com o orientador (ponto 2): a ordem de atualização por número de conta é controle técnico, classificado como infraestrutura. Regra redigida antes da decisão: Se o número da conta de origem for menor que o número da conta de destino, a conta de origem é a primeira a ser atualizada. O IF da linha 378 vem antes do comentário e aparece como [cab.]. O comentário e o código só selecionam a conta de origem (MOVE para DESIRED-ACC-NO); a atualização está nas linhas seguintes (XFRFUN-007 e 008). Nenhum comentário do fonte explica por que a ordem depende do número da conta. O programa trata deadlock do DB2 com retentativas (DB2-DEADLOCK-RETRY), o que sugere controle de concorrência, mas isso é inferência. Decidir com o orientador se é regra de negócio ou infraestrutura. | N27: 1
A28: XFRFUN-008 | B28: XFRFUN | C28: 392 | D28: 394-398 | E28: If the update was successful, update the TO account | F28: IF COMM-SUCCESS = 'Y' MOVE COMM-TACCNO TO DESIRED-ACC-NO MOVE COMM-TSCODE TO DESIRED-SORT-CODE PERFORM UPDATE-ACCOUNT-DB2-TO | G28: Decisão | H28: IF | J28: Se a atualização da conta de origem for bem-sucedida, a conta de destino é atualizada. | K28: regra de negócio | L28: Validado | M28: Ramo em que o número da conta de origem é menor que o da conta de destino (XFRFUN-006). A ordem de atualização por número de conta foi classificada como infraestrutura na reunião com o orientador (XFRFUN-006 e 017). Estrutura espelhada na XFRFUN-019 (ordem inversa). Falhas seguem para rollback/ABEND (XFRFUN-009 a 015). | N28: 1 | P28: Não
A29: XFRFUN-009 | B29: XFRFUN | C29: 401-402 | D29: 404-413 | E29: If the update to the TO account was unsuccessful then we need to flag it and roll it back | F29: IF COMM-SUCCESS = 'N' IF COMM-FAIL-CODE = '2' EXEC CICS SYNCPOINT ROLLBACK RESP(WS-CICS-RESP) RESP2(WS-CICS-RESP2) END-EXEC IF WS-CICS-RESP IS NOT EQUAL TO DFHRESP(NORMAL) | G29: Decisão e falha | H29: IF, falha | K29: infraestrutura (excluída) | L29: Validado | M29: Falha na atualização da conta de destino (COMM-SUCCESS = 'N') com código '2': rollback; se o rollback falhar, ABEND (010 e 011); com outro código, ABEND 'TO' (012). Fluxo de rollback/ABEND, tratado como infraestrutura. O efeito de negócio (transferência não efetivada pela metade) decorre do rollback: decidir se deve virar regra. | N29: 3
A30: XFRFUN-010 | B30: XFRFUN | C30: 415-418 | D30: 420-422 | E30: Preserve the RESP and RESP2, then set up the standard ABEND info before getting the applid, date/time etc. and linking to the Abend Handler program. | F30: INITIALIZE ABNDINFO-REC MOVE EIBRESP TO ABND-RESPCODE MOVE EIBRESP2 TO ABND-RESP2CODE | G30: Falha | H30: falha | K30: infraestrutura (excluída) | L30: Validado | M30: Montagem padrão das informações de ABEND (INITIALIZE ABNDINFO-REC; MOVE EIBRESP/EIBRESP2); tratamento técnico sem semântica bancária. | N30: 0
A31: XFRFUN-011 | B31: XFRFUN | C31: 424 | D31: 426-481 | E31: Get supplemental information | F31: EXEC CICS ASSIGN APPLID(ABND-APPLID) END-EXEC MOVE EIBTASKN TO ABND-TASKNO-KEY MOVE EIBTRNID TO ABND-TRANID PERFORM POPULATE-TIME-DATE MOVE WS-ORIG-DATE TO ABND-DATE STRING WS-TIME-NOW-GRP-HH DELIMITED BY SIZE, ':' DELIMITED BY SIZE, WS-TIME-NOW-GRP-MM DELIMITED BY SIZE, ':' DELIMITED BY SIZE, WS-TIME-NOW-GRP-MM DELIMITED BY SIZE INTO ABND-TIME END-STRING MOVE WS-U-TIME TO ABND-UTIME-KEY MOVE 'HROL' TO ABND-CODE EXEC CICS ASSIGN PROGRAM(ABND-PROGRAM) END-EXEC MOVE ZEROS TO ABND-SQLCODE STRING 'UAD010(2) - Error on SYNCPOINT' DELIMITED BY SIZE, ' ROLLBACK' DELIMITED BY SIZE, ' after UPDATING TO account ' DELIMITED BY SIZE, ' EIBRESP=' DELIMITED BY SIZE, ABND-RESPCODE DELIMITED BY SIZE, ' RESP2=' DELIMITED BY SIZE, ABND-RESP2CODE DELIMITED BY SIZE INTO ABND-FREEFORM END-STRING EXEC CICS LINK PROGRAM(WS-ABEND-PGM) COMMAREA(ABNDINFO-REC) END-EXEC DISPLAY 'XFRFUN error syncpoint rollback' ' after updating TO account ' ',RESP=' WS-CICS-RESP ',RESP2=' WS-CICS-RESP2 EXEC CICS ABEND ABCODE('HROL') NODUMP CANCEL END-EXEC END-IF GO TO UAD999 ELSE | G31: Falha | H31: falha | I31: comentário curto; contém GO TO (desvio incondicional) | K31: infraestrutura (excluída) | L31: Validado | M31: Coleta de informações complementares de ABEND (PERFORM POPULATE-TIME-DATE, LINK ao tratador de ABEND, ABEND); tratamento técnico sem semântica bancária. Termina com GO TO UAD999; o ELSE da linha 481 é o cabeçalho do comentário seguinte. | N31: 0
A32: XFRFUN-012 | B32: XFRFUN | C32: 483-484 | D32: 486-496 | E32: If the COMM-FLAG is anything else other than 2 then abend. | F32: DISPLAY 'Error updating TO account' EXEC CICS ABEND ABCODE('TO ') NODUMP END-EXEC END-IF END-IF ELSE | G32: Falha | H32: falha | K32: infraestrutura (excluída) | L32: Validado | M32: ABEND 'TO' quando o código de falha da conta de destino não é '2'. O comentário cita COMM-FLAG, mas o código testa COMM-FAIL-CODE. Tratamento de ABEND. | N32: 0
A33: XFRFUN-013 | B33: XFRFUN | C33: 498-499 | D33: 501-507 | E33: If the update to the FROM account was not successful rollback. | F33: IF COMM-FAIL-CODE = '1' EXEC CICS SYNCPOINT ROLLBACK RESP(WS-CICS-RESP) RESP2(WS-CICS-RESP2) END-EXEC | G33: Decisão | H33: IF | K33: infraestrutura (excluída) | L33: Validado | M33: Rollback quando a atualização da conta de origem falha com código '1'. O comentário diz apenas 'not successful', mas o código testa COMM-FAIL-CODE = '1'. Infraestrutura transacional. | N33: 1
A34: XFRFUN-014 | B34: XFRFUN | C34: 510 | D34: 512-526 | E34: If the ROLLback failed | F34: IF WS-CICS-RESP IS NOT EQUAL TO DFHRESP(NORMAL) DISPLAY 'XFRFUN error syncpoint ' ' rollback after ' 'updating FROM account ' ',RESP=' WS-CICS-RESP ',RESP2=' WS-CICS-RESP2 EXEC CICS ABEND ABCODE('HROL') NODUMP END-EXEC END-IF GO TO UAD999 ELSE | G34: Decisão e falha | H34: IF, falha | I34: contém GO TO (desvio incondicional) | K34: infraestrutura (excluída) | L34: Validado | M34: Falha do rollback após atualizar a conta de origem: DISPLAY e ABEND 'HROL'; infraestrutura. | N34: 1
A35: XFRFUN-015 | B35: XFRFUN | C35: 528-531 | D35: 533-535 | E35: Preserve the RESP and RESP2, then set up the standard ABEND info before getting the applid, date/time etc. and linking to the Abend Handler program. | F35: INITIALIZE ABNDINFO-REC MOVE EIBRESP TO ABND-RESPCODE MOVE EIBRESP2 TO ABND-RESP2CODE | G35: Falha | H35: falha | K35: infraestrutura (excluída) | L35: Validado | M35: Montagem padrão das informações de ABEND (INITIALIZE ABNDINFO-REC; MOVE EIBRESP/EIBRESP2); tratamento técnico sem semântica bancária. | N35: 0
A36: XFRFUN-016 | B36: XFRFUN | C36: 537 | D36: 539-589 | E36: Get supplemental information | F36: EXEC CICS ASSIGN APPLID(ABND-APPLID) END-EXEC MOVE EIBTASKN TO ABND-TASKNO-KEY MOVE EIBTRNID TO ABND-TRANID PERFORM POPULATE-TIME-DATE MOVE WS-ORIG-DATE TO ABND-DATE STRING WS-TIME-NOW-GRP-HH DELIMITED BY SIZE, ':' DELIMITED BY SIZE, WS-TIME-NOW-GRP-MM DELIMITED BY SIZE, ':' DELIMITED BY SIZE, WS-TIME-NOW-GRP-MM DELIMITED BY SIZE INTO ABND-TIME END-STRING MOVE WS-U-TIME TO ABND-UTIME-KEY MOVE 'FROM' TO ABND-CODE EXEC CICS ASSIGN PROGRAM(ABND-PROGRAM) END-EXEC MOVE ZEROS TO ABND-SQLCODE STRING 'UAD010(3) - Error updating FROM account ' DELIMITED BY SIZE, ' EIBRESP=' DELIMITED BY SIZE, ABND-RESPCODE DELIMITED BY SIZE, ' RESP2=' DELIMITED BY SIZE, ABND-RESP2CODE DELIMITED BY SIZE INTO ABND-FREEFORM END-STRING EXEC CICS LINK PROGRAM(WS-ABEND-PGM) COMMAREA(ABNDINFO-REC) END-EXEC DISPLAY 'Error updating FROM account' EXEC CICS ABEND ABCODE('FROM') NODUMP CANCEL END-EXEC END-IF END-IF ELSE | G36: Falha | H36: falha | I36: comentário curto | K36: infraestrutura (excluída) | L36: Validado | M36: Coleta de informações complementares de ABEND (PERFORM POPULATE-TIME-DATE, LINK ao tratador de ABEND, ABEND); tratamento técnico sem semântica bancária. O ELSE da linha 589, no fim do trecho, é o cabeçalho da XFRFUN-017. | N36: 0
