Workbook

Sheet Legenda
A1: Gabarito (ground-truth): pares candidatos de comentário e código
A3: Origem | B3: Programas da CBSA na pasta ORIGINAL do repositório da base de dados (commit e22475691524ef72a92ee77f7040233e098ab1b9, ijmitch/cics-banking-sample-application-cbsa). Números de linha referem-se aos arquivos do ORIGINAL.
A4: Como foi gerado | B4: Extração automática (script extrair_pares_gabarito_adaptado.py). Cada bloco de comentário da PROCEDURE DIVISION é pareado ao código que o segue, até o próximo comentário (limite de 30 linhas por trecho).
A5: Filtro (E4, seção 1.3) | B5: Retido: trecho com IF, EVALUATE ou WHEN, ou com tratamento de falha (ABEND, SQLCODE, HANDLE, DFHRESP, EIBRESP, EIBRCODE). O filtro é sintático: trechos de infraestrutura pura (rollback, ABEND de DB2/VSAM, storm drain) também aparecem aqui, porque contêm essas palavras-chave — a exclusão semântica é feita na revisão manual (coluna Categoria), não pelo script. Os demais (sem decisão nem falha) ficam na aba Descartados, para que o critério seja auditável.
A6: O que preencher | B6: Aba Candidatos, colunas J a M (fundo amarelo): Regra de negócio extraída, Categoria, Status e Observação — mesmas colunas usadas na revisão manual do DBCRFUN. Na aba Descartados, coluna I.
A7: Valores da revisão | B7: Categoria: regra de negócio, infraestrutura (excluída) ou a discutir (lista suspensa). Status: A validar ou Validado. Em Descartados: Manter descartado ou Reincluir.
A8: Alertas | B8: possível código desativado: o comentário parece uma instrução COBOL comentada. comentário curto: até 3 palavras. trecho truncado: o código do par passa do limite de linhas; conferir o restante no fonte. comentários adjacentes fundidos: o bloco seguinte de comentário foi unido porque o trecho entre eles não tinha código ativo. comentário menciona condição (aba Descartados): o comentário descreve uma condição, mas o trecho seguinte é só ação; a decisão pode estar antes no fonte.
A9: Limitações | B9: A triagem é heurística e não substitui a revisão dupla. Comentários de cabeçalho (antes da PROCEDURE DIVISION) não entram. Linhas de depuração (indicador D) aparecem com o prefixo [D]. O tipo (Decisão, Falha, Decisão e falha) é atribuído ao trecho inteiro, não ao comentário isolado.
A11: Exemplo de regra atômica | B11: Ilustrativo, não faz parte do gabarito: "Se o valor solicitado for um débito e o saldo disponível for insuficiente, a solicitação é negada." (uma condição e uma consequência por regra)

Sheet Resumo
A1: Programa | B1: Blocos com texto | C1: Candidatos retidos | D1: Descartados | E1: Decisão | F1: Falha | G1: Decisão e falha | H1: Com alertas | I1: Regra de negócio | J1: Infraestrutura (excluída) | K1: A discutir | L1: Validados | M1: Pendentes
A2: DBCRFUN | B2: =C2+D2 | C2: =COUNTIF(Candidatos!$B:$B,$A2) | D2: =COUNTIF(Descartados!$B:$B,$A2) | E2: =COUNTIFS(Candidatos!$B:$B,$A2,Candidatos!$G:$G,"Decisão") | F2: =COUNTIFS(Candidatos!$B:$B,$A2,Candidatos!$G:$G,"Falha") | G2: =COUNTIFS(Candidatos!$B:$B,$A2,Candidatos!$G:$G,"Decisão e falha") | H2: =COUNTIFS(Candidatos!$B:$B,$A2,Candidatos!$I:$I,"<>") | I2: =COUNTIFS(Candidatos!$B:$B,$A2,Candidatos!$K:$K,"regra de negócio") | J2: =COUNTIFS(Candidatos!$B:$B,$A2,Candidatos!$K:$K,"infraestrutura (excluída)") | K2: =COUNTIFS(Candidatos!$B:$B,$A2,Candidatos!$K:$K,"a discutir") | L2: =COUNTIFS(Candidatos!$B:$B,$A2,Candidatos!$L:$L,"Validado") | M2: =C2-L2
A3: XFRFUN | B3: =C3+D3 | C3: =COUNTIF(Candidatos!$B:$B,$A3) | D3: =COUNTIF(Descartados!$B:$B,$A3) | E3: =COUNTIFS(Candidatos!$B:$B,$A3,Candidatos!$G:$G,"Decisão") | F3: =COUNTIFS(Candidatos!$B:$B,$A3,Candidatos!$G:$G,"Falha") | G3: =COUNTIFS(Candidatos!$B:$B,$A3,Candidatos!$G:$G,"Decisão e falha") | H3: =COUNTIFS(Candidatos!$B:$B,$A3,Candidatos!$I:$I,"<>") | I3: =COUNTIFS(Candidatos!$B:$B,$A3,Candidatos!$K:$K,"regra de negócio") | J3: =COUNTIFS(Candidatos!$B:$B,$A3,Candidatos!$K:$K,"infraestrutura (excluída)") | K3: =COUNTIFS(Candidatos!$B:$B,$A3,Candidatos!$K:$K,"a discutir") | L3: =COUNTIFS(Candidatos!$B:$B,$A3,Candidatos!$L:$L,"Validado") | M3: =C3-L3
A4: BNK1CRA | B4: =C4+D4 | C4: =COUNTIF(Candidatos!$B:$B,$A4) | D4: =COUNTIF(Descartados!$B:$B,$A4) | E4: =COUNTIFS(Candidatos!$B:$B,$A4,Candidatos!$G:$G,"Decisão") | F4: =COUNTIFS(Candidatos!$B:$B,$A4,Candidatos!$G:$G,"Falha") | G4: =COUNTIFS(Candidatos!$B:$B,$A4,Candidatos!$G:$G,"Decisão e falha") | H4: =COUNTIFS(Candidatos!$B:$B,$A4,Candidatos!$I:$I,"<>") | I4: =COUNTIFS(Candidatos!$B:$B,$A4,Candidatos!$K:$K,"regra de negócio") | J4: =COUNTIFS(Candidatos!$B:$B,$A4,Candidatos!$K:$K,"infraestrutura (excluída)") | K4: =COUNTIFS(Candidatos!$B:$B,$A4,Candidatos!$K:$K,"a discutir") | L4: =COUNTIFS(Candidatos!$B:$B,$A4,Candidatos!$L:$L,"Validado") | M4: =C4-L4
A5: BNK1TFN | B5: =C5+D5 | C5: =COUNTIF(Candidatos!$B:$B,$A5) | D5: =COUNTIF(Descartados!$B:$B,$A5) | E5: =COUNTIFS(Candidatos!$B:$B,$A5,Candidatos!$G:$G,"Decisão") | F5: =COUNTIFS(Candidatos!$B:$B,$A5,Candidatos!$G:$G,"Falha") | G5: =COUNTIFS(Candidatos!$B:$B,$A5,Candidatos!$G:$G,"Decisão e falha") | H5: =COUNTIFS(Candidatos!$B:$B,$A5,Candidatos!$I:$I,"<>") | I5: =COUNTIFS(Candidatos!$B:$B,$A5,Candidatos!$K:$K,"regra de negócio") | J5: =COUNTIFS(Candidatos!$B:$B,$A5,Candidatos!$K:$K,"infraestrutura (excluída)") | K5: =COUNTIFS(Candidatos!$B:$B,$A5,Candidatos!$K:$K,"a discutir") | L5: =COUNTIFS(Candidatos!$B:$B,$A5,Candidatos!$L:$L,"Validado") | M5: =C5-L5
A6: TOTAL | B6: =SUM(B2:B5) | C6: =SUM(C2:C5) | D6: =SUM(D2:D5) | E6: =SUM(E2:E5) | F6: =SUM(F2:F5) | G6: =SUM(G2:G5) | H6: =SUM(H2:H5) | I6: =SUM(I2:I5) | ... L6: =SUM(L2:L5)
A8: Contagens por fórmula: atualizam conforme a revisão é preenchida na aba Candidatos.

Sheet Candidatos
A1: ID | B1: Programa | C1: Linhas do comentário | D1: Linhas do código | E1: Comentário | F1: Trecho de código | G1: Tipo | H1: Estruturas | I1: Alertas | J1: Regra de negócio extraída | K1: Categoria | L1: Status | M1: Observação
A2: DBCRFUN-001 | B2: DBCRFUN | C2: 205 | D2: 207-212 | E2: Set up some Abend handling | F2: EXEC CICS HANDLE ABEND LABEL(ABEND-HANDLING) END-EXEC. MOVE SORTCODE TO COMM-SORTC. MOVE SORTCODE TO DESIRED-SORT-CODE. | G2: Falha | H2: falha | L2: A validar
A3: DBCRFUN-005 | B3: DBCRFUN | C3: 276-277 | D3: 279-287 | E3: Check that select was successful. If it wasn't then deal with it | F3: IF SQLCODE NOT = 0 MOVE 'N' TO COMM-SUCCESS IF SQLCODE = +100 MOVE '1' TO COMM-FAIL-CODE ELSE MOVE '2' TO COMM-FAIL-CODE END-IF | G3: Decisão e falha | H3: IF, falha | L3: A validar
A4: DBCRFUN-007 | B4: DBCRFUN | C4: 301-304 | D4: 307 | E4: Is the amount being requested a debit or a credit? If it is a CREDIT (+) then we don't need to ensure that the available balance has sufficient funds, because this is money coming in. | F4: IF COMM-AMT < 0 | G4: Decisão | H4: IF | L4: A validar
A5: DBCRFUN-008 | B5: DBCRFUN | C5: 309-328 | D5: 316-352 | E5: The amount being requested is a DEBIT/Payment (-) so we do need to check that the available balance is sufficient to cover the amount being asked for. If there are NOT sufficient funds the request is denied so remove the record LOCK and and finish. Check to see whether the Payment is being requested from a MORTGAGE or LOAN account. We only make this check for PAYMENTs (we don't make this check for requests via the Teller). How do we know it is a PAYMENT as opposed to a Teller, this is determined by the COMM-FACILTYPE(496 = NONE) If it is a PAYMENT being requested from a MORTGAGE or LOAN account then set an appropriate fail code (4) and finish up. | F5: [D] DISPLAY 'COMM-AMT IS negative' IF (HV-ACCOUNT-ACC-TYPE = 'MORTGAGE' AND COMM-FACILTYPE = 496) OR (HV-ACCOUNT-ACC-TYPE = 'LOAN ' AND COMM-FACILTYPE = 496) MOVE 'N' TO COMM-SUCCESS MOVE '4' TO COMM-FAIL-CODE GO TO UAD999 END-IF MOVE 0 TO WS-DIFFERENCE COMPUTE WS-DIFFERENCE = HV-ACCOUNT-AVAIL-BAL + COMM-AMT IF WS-DIFFERENCE < 0 AND COMM-FACILTYPE = 496 [D] DISPLAY 'insufficient funds!' MOVE 'N' TO COMM-SUCCESS MOVE '3' TO COMM-FAIL-CODE GO TO UAD999 END-IF END-IF. | G5: Decisão | H5: IF | I5: comentários adjacentes fundidos | L5: A validar
A6: DBCRFUN-009 | B6: DBCRFUN | C6: 356-366 | D6: 368-376 | E6: Check to see whether a Credit is being requested from a MORTGAGE or LOAN account. We only make this check for requests via the PAYMENT link (we don't make this check for requests via the Teller). How do we know it is a PAYMENT as opposed to a Teller, this is determined by the COMM-FACILTYPE(496 = NONE) If it is a PAYMENT credit being requested from a MORTGAGE or LOAN account then set an appropriate fail code (4), remove the record lock and finish up. | F6: IF (HV-ACCOUNT-ACC-TYPE = 'MORTGAGE' AND COMM-FACILTYPE = 496) OR (HV-ACCOUNT-ACC-TYPE = 'LOAN ' AND COMM-FACILTYPE = 496) MOVE 'N' TO COMM-SUCCESS MOVE '4' TO COMM-FAIL-CODE GO TO UAD999 END-IF. | G6: Decisão | H6: IF | L6: A validar
A7: DBCRFUN-012 | B7: DBCRFUN | C7: 411-412 | D7: 414-419 | E7: If the rewrite was successful then we need to pass back the amended available balance and actual balance. | F7: MOVE SQLCODE TO SQLCODE-DISPLAY. MOVE HV-ACCOUNT-AVAIL-BAL TO COMM-AV-BAL. MOVE HV-ACCOUNT-ACTUAL-BAL TO COMM-ACT-BAL. | G7: Falha | H7: falha | L7: A validar
A8: DBCRFUN-013 | B8: DBCRFUN | C8: 422-423 | D8: 425-427 | E8: If the RESP CODE was NOT OK then we need to set flags accordingly | F8: IF SQLCODE NOT = 0 MOVE 'N' TO COMM-SUCCESS MOVE '2' TO COMM-FAIL-CODE | G8: Decisão e falha | H8: IF, falha | L8: A validar
A9: DBCRFUN-017 | B9: DBCRFUN | C9: 473 | D9: 475-493 | E9: Populate the current time and date | F9: EXEC CICS ASKTIME ABSTIME(WS-U-TIME) END-EXEC. EXEC CICS FORMATTIME ABSTIME(WS-U-TIME) DDMMYYYY(WS-ORIG-DATE) TIME(HV-PROCTRAN-TIME) DATESEP('.') END-EXEC. MOVE WS-ORIG-DATE TO WS-ORIG-DATE-GRP-X. MOVE WS-ORIG-DATE-GRP-X TO HV-PROCTRAN-DATE. MOVE SPACES TO HV-PROCTRAN-DESC. IF COMM-AMT < 0 MOVE 'DEB' TO HV-PROCTRAN-TYPE MOVE 'COUNTER WTHDRW' TO HV-PROCTRAN-DESC | G9: Decisão | H9: IF | L9: A validar
A10: DBCRFUN-018 | B10: DBCRFUN | C10: 496 | D10: 498-506 | E10: If it is a debit from a PAYMENT | F10: IF COMM-FACILTYPE = 496 MOVE 'PDR' TO HV-PROCTRAN-TYPE MOVE COMM-ORIGIN(1:14) TO HV-PROCTRAN-DESC END-IF ELSE MOVE 'CRE' TO HV-PROCTRAN-TYPE MOVE 'COUNTER RECVED' TO HV-PROCTRAN-DESC | G10: Decisão | H10: IF | L10: A validar
A11: DBCRFUN-019 | B11: DBCRFUN | C11: 509 | D11: 511-519 | E11: If it is a credit from a PAYMENT | F11: IF COMM-FACILTYPE = 496 MOVE 'PCR' TO HV-PROCTRAN-TYPE MOVE COMM-ORIGIN(1:14) TO HV-PROCTRAN-DESC END-IF END-IF. MOVE COMM-AMT TO HV-PROCTRAN-AMOUNT. | G11: Decisão | H11: IF | L11: A validar
A12: DBCRFUN-021 | B12: DBCRFUN | C12: 552 | D12: 554-559 | E12: Check the SQLCODE | F12: IF SQLCODE NOT = 0 MOVE SQLCODE TO SQLCODE-DISPLAY DISPLAY 'UNABLE TO WRITE TO PROCTRAN DB2 DATASTORE' ' SQLCODE=' SQLCODE-DISPLAY 'WITH THE FOLLOWING DATA:' HOST-PROCTRAN-ROW | G12: Decisão e falha | H12: IF, falha | I12: comentário curto | L12: A validar
A13: DBCRFUN-022 | B13: DBCRFUN | C13: 561-562 | D13: 564-569 | E13: You need to issue a ROLLBACK to get rid of the updated ACCOUNT record | F13: EXEC CICS SYNCPOINT ROLLBACK RESP(WS-CICS-RESP) RESP2(WS-CICS-RESP2) END-EXEC IF WS-CICS-RESP NOT = DFHRESP(NORMAL) | G13: Decisão e falha | H13: IF, falha | L13: A validar
A14: DBCRFUN-023 | B14: DBCRFUN | C14: 571-574 | D14: 576-578 | E14: Preserve the RESP and RESP2, then set up the standard ABEND info before getting the applid, date/time etc. and linking to the Abend Handler program. | F14: INITIALIZE ABNDINFO-REC MOVE EIBRESP TO ABND-RESPCODE MOVE EIBRESP2 TO ABND-RESP2CODE | G14: Falha | H14: falha | L14: A validar
A15: DBCRFUN-027 | B15: DBCRFUN | C15: 671-672 | D15: 675-695 | E15: Check if the Sqclode that is returned one that will trigger Storm Drain is active in Workload | F15: EVALUATE SQLCODE WHEN 923 MOVE 'DB2 Connection lost ' TO STORM-DRAIN-CONDITION WHEN OTHER MOVE 'Not Storm Drain ' TO STORM-DRAIN-CONDITION END-EVALUATE. IF STORM-DRAIN-CONDITION NOT EQUAL 'Not Storm Drain ' DISPLAY 'DBCRFUN: Check-For-Storm-Drain-DB2: Storm ' 'Drain condition (' STORM-DRAIN-CONDITION ') ' 'has been met (' SQLCODE-DISPLAY ').' ELSE CONTINUE END-IF. CFSDD999. EXIT. | G15: Decisão e falha | H15: IF, EVALUATE, WHEN, falha | L15: A validar
A16: DBCRFUN-029 | B16: DBCRFUN | C16: 708-713 | D16: 716 | E16: Evaluate the Abend code that is returned - For DB2 AD2Z ... provide some diagnostics - For VSAM RLS abends: AFCR, AFCS and AFCT record the Abend as happening but do not abend ... leave this to CPSM WLM "Storm drain" (Abend probability) to handle If not a "storm drain" ... take the abend afterwards | F16: EVALUATE MY-ABEND-CODE | G16: Decisão | H16: EVALUATE | L16: A validar
A17: DBCRFUN-030 | B17: DBCRFUN | C17: 718 | D17: 720-735 | E17: DB2 AD2Z abend | F17: WHEN 'AD2Z' MOVE SQLCODE TO SQLCODE-DISPLAY DISPLAY 'DB2 DEADLOCK DETECTED IN DBCRFUN, SQLCODE=' SQLCODE-DISPLAY DISPLAY 'DB2 DEADLOCK FOR ACCOUNT ' HV-ACCOUNT-ACC-NO DISPLAY 'SQLSTATE=' SQLSTATE ',SQLERRMC=' SQLERRMC(1:SQLERRML) ',SQLERRD(1)=' SQLERRD(1) ',SQLERRD(2)=' SQLERRD(2) ',SQLERRD(3)=' SQLERRD(3) ',SQLERRD(4)=' SQLERRD(4) ',SQLERRD(5)=' SQLERRD(5) ',SQLERRD(6)=' SQLERRD(6) | G17: Decisão e falha | H17: WHEN, falha | I17: comentário curto | L17: A validar
A18: DBCRFUN-031 | B18: DBCRFUN | C18: 738-740 | D18: 742-756 | E18: VSAM RLS abends, subject to CPSM WLM Storm Drain check if handled (as here) and Workload Abend Thresholds are set. | F18: WHEN 'AFCR' WHEN 'AFCS' WHEN 'AFCT' MOVE 'Y' TO WS-STORM-DRAIN DISPLAY 'DBCRFUN: Check-For-Storm-Drain-VSAM: Storm ' 'Drain condition (Abend ' MY-ABEND-CODE ') ' 'has been met.' EXEC CICS SYNCPOINT ROLLBACK RESP(WS-CICS-RESP) RESP2(WS-CICS-RESP2) END-EXEC IF WS-CICS-RESP NOT = DFHRESP(NORMAL) | G18: Decisão e falha | H18: IF, WHEN, falha | L18: A validar
A19: DBCRFUN-032 | B19: DBCRFUN | C19: 758-761 | D19: 763-765 | E19: Preserve the RESP and RESP2, then set up the standard ABEND info before getting the applid, date/time etc. and linking to the Abend Handler program. | F19: INITIALIZE ABNDINFO-REC MOVE EIBRESP TO ABND-RESPCODE MOVE EIBRESP2 TO ABND-RESP2CODE | G19: Falha | H19: falha | L19: A validar
A20: XFRFUN-001 | B20: XFRFUN | C20: 286-287 | D20: 289-296 | E20: If the amount being transferred is negative, then flag this as a failure and finish. | F20: IF COMM-AMT <= ZERO MOVE 'N' TO COMM-SUCCESS MOVE '4' TO COMM-FAIL-CODE PERFORM GET-ME-OUT-OF-HERE END-IF. PERFORM UPDATE-ACCOUNT-DB2 | G20: Decisão | H20: IF | L20: A validar
A21: XFRFUN-003 | B21: XFRFUN | C21: 313-314 | D21: 316-317 | E21: Are we trying to transfer from and to the same account? We don't allow that. | F21: IF COMM-FACCNO = COMM-TACCNO AND COMM-FSCODE = COMM-TSCODE | G21: Decisão | H21: IF | L21: A validar
A22: XFRFUN-004 | B22: XFRFUN | C22: 319-322 | D22: 324-326 | E22: Preserve the RESP and RESP2, then set up the standard ABEND info before getting the applid, date/time etc. and linking to the Abend Handler program. | F22: INITIALIZE ABNDINFO-REC MOVE EIBRESP TO ABND-RESPCODE MOVE EIBRESP2 TO ABND-RESP2CODE | G22: Falha | H22: falha | L22: A validar
A23: XFRFUN-008 | B23: XFRFUN | C23: 392 | D23: 394-398 | E23: If the update was successful, update the TO account | F23: IF COMM-SUCCESS = 'Y' MOVE COMM-TACCNO TO DESIRED-ACC-NO MOVE COMM-TSCODE TO DESIRED-SORT-CODE PERFORM UPDATE-ACCOUNT-DB2-TO | G23: Decisão | H23: IF | L23: A validar
A24: XFRFUN-009 | B24: XFRFUN | C24: 401-402 | D24: 404-413 | E24: If the update to the TO account was unsuccessful then we need to flag it and roll it back | F24: IF COMM-SUCCESS = 'N' IF COMM-FAIL-CODE = '2' EXEC CICS SYNCPOINT ROLLBACK RESP(WS-CICS-RESP) RESP2(WS-CICS-RESP2) END-EXEC IF WS-CICS-RESP IS NOT EQUAL TO DFHRESP(NORMAL) | G24: Decisão e falha | H24: IF, falha | L24: A validar
A25: XFRFUN-010 | B25: XFRFUN | C25: 415-418 | D25: 420-422 | E25: Preserve the RESP and RESP2, then set up the standard ABEND info before getting the applid, date/time etc. and linking to the Abend Handler program. | F25: INITIALIZE ABNDINFO-REC MOVE EIBRESP TO ABND-RESPCODE MOVE EIBRESP2 TO ABND-RESP2CODE | G25: Falha | H25: falha | L25: A validar
A26: XFRFUN-012 | B26: XFRFUN | C26: 483-484 | D26: 486-496 | E26: If the COMM-FLAG is anything else other than 2 then abend. | F26: DISPLAY 'Error updating TO account' EXEC CICS ABEND ABCODE('TO ') NODUMP END-EXEC END-IF END-IF ELSE | G26: Falha | H26: falha | L26: A validar
A27: XFRFUN-013 | B27: XFRFUN | C27: 498-499 | D27: 501-507 | E27: If the update to the FROM account was not successful rollback. | F27: IF COMM-FAIL-CODE = '1' EXEC CICS SYNCPOINT ROLLBACK RESP(WS-CICS-RESP) RESP2(WS-CICS-RESP2) END-EXEC | G27: Decisão | H27: IF | L27: A validar
A28: XFRFUN-014 | B28: XFRFUN | C28: 510 | D28: 512-526 | E28: If the ROLLback failed | F28: IF WS-CICS-RESP IS NOT EQUAL TO DFHRESP(NORMAL) DISPLAY 'XFRFUN error syncpoint ' ' rollback after ' 'updating FROM account ' ',RESP=' WS-CICS-RESP ',RESP2=' WS-CICS-RESP2 EXEC CICS ABEND ABCODE('HROL') NODUMP END-EXEC END-IF GO TO UAD999 ELSE | G28: Decisão e falha | H28: IF, falha | L28: A validar
A29: XFRFUN-015 | B29: XFRFUN | C29: 528-531 | D29: 533-535 | E29: Preserve the RESP and RESP2, then set up the standard ABEND info before getting the applid, date/time etc. and linking to the Abend Handler program. | F29: INITIALIZE ABNDINFO-REC MOVE EIBRESP TO ABND-RESPCODE MOVE EIBRESP2 TO ABND-RESP2CODE | G29: Falha | H29: falha | L29: A validar
... A45: XFRFUN-049 | B45: XFRFUN | C45: 1293-1296 | D45: 1298-1300 | E45: Preserve the RESP and RESP2, then set up the standard ABEND info before getting the applid, date/time etc. and linking to the Abend Handler program. | F45: INITIALIZE ABNDINFO-REC MOVE EIBRESP TO ABND-RESPCODE MOVE EIBRESP2 TO ABND-RESP2CODE | G45: Falha | H45: falha | L45: A validar
A46: XFRFUN-050 | B46: XFRFUN | C46: 1302 | D46: 1304-1342 | E46: Get supplemental information | F46: EXEC CICS ASSIGN APPLID(ABND-APPLID) END-EXEC MOVE EIBTASKN TO ABND-TASKNO-KEY MOVE EIBTRNID TO ABND-TRANID PERFORM POPULATE-TIME-DATE MOVE WS-ORIG-DATE TO ABND-DATE STRING WS-TIME-NOW-GRP-HH DELIMITED BY SIZE, ':' DELIMITED BY SIZE, WS-TIME-NOW-GRP-MM DELIMITED BY SIZE, ':' DELIMITED BY SIZE, WS-TIME-NOW-GRP-MM DELIMITED BY SIZE INTO ABND-TIME END-STRING MOVE WS-U-TIME TO ABND-UTIME-KEY MOVE 'RUF2' TO ABND-CODE EXEC CICS ASSIGN PROGRAM(ABND-PROGRAM) END-EXEC MOVE ZEROS TO ABND-SQLCODE IF SQLERRD(3) = 13172894 STRING 'UAD010-TO(3) - timeout detected ' DELIMITED BY SIZE, ' EIBRESP=' DELIMITED BY SIZE, ABND-RESPCODE DELIMITED BY SIZE, 'RESP2=' DELIMITED BY SIZE, ABND-RESP2CODE DELIMITED BY SIZE INTO ABND-FREEFORM END-STRING END-IF EXEC CICS LINK PROGRAM(WS-ABEND-PGM) COMMAREA(ABNDINFO-REC) | G46: Decisão | H46: IF | I46: comentário curto; trecho truncado (30 linhas) | L46: A validar
A47: XFRFUN-052 | B47: XFRFUN | C47: 1382 | D47: 1384-1389 | E47: If the RESP CODE was NOT OK then we need to abend | F47: IF SQLCODE NOT = 0 MOVE SQLCODE TO SQLCODE-DISPLAY DISPLAY 'UNABLE TO UPDATE TO ACCOUNT.' HV-ACCOUNT-SORTCODE HV-ACCOUNT-ACC-NO 'THE SQLCODE=' SQLCODE-DISPLAY ' SQLERRD(3) ' SQLERRD(3) | G47: Decisão e falha | H47: IF, falha | L47: A validar
A48: XFRFUN-053 | B48: XFRFUN | C48: 1392-1393 | D48: 1395-1409 | E48: Check if SQLCODE indicates that Storm Drain processing is applicable in a workload if activated | F48: PERFORM CHECK-FOR-STORM-DRAIN-DB2 IF SQLCODE = -911 IF SQLERRD(3) = 13172872 DISPLAY 'DEADLOCK DETECTED!' ADD 1 TO DB2-DEADLOCK-RETRY IF DB2-DEADLOCK-RETRY < 6 EXEC CICS SYNCPOINT ROLLBACK RESP(WS-CICS-RESP) RESP2(WS-CICS-RESP2) END-EXEC IF WS-CICS-RESP IS NOT EQUAL TO DFHRESP(NORMAL) | G48: Decisão e falha | H48: IF, falha | L48: A validar
A49: XFRFUN-054 | B49: XFRFUN | C49: 1412-1415 | D49: 1417-1419 | E49: Preserve the RESP and RESP2, then set up the standard ABEND info before getting the applid, date/time etc. and linking to the Abend Handler program. | F49: INITIALIZE ABNDINFO-REC MOVE EIBRESP TO ABND-RESPCODE MOVE EIBRESP2 TO ABND-RESP2CODE | G49: Falha | H49: falha | L49: A validar
A50: XFRFUN-056 | B50: XFRFUN | C50: 1493-1496 | D50: 1498-1500 | E50: Preserve the RESP and RESP2, then set up the standard ABEND info before getting the applid, date/time etc. and linking to the Abend Handler program. | F50: INITIALIZE ABNDINFO-REC MOVE EIBRESP TO ABND-RESPCODE MOVE EIBRESP2 TO ABND-RESP2CODE | G50: Falha | H50: falha | L50: A validar
A51: XFRFUN-057 | B51: XFRFUN | C51: 1502 | D51: 1504-1542 | E51: Get supplemental information | F51: EXEC CICS ASSIGN APPLID(ABND-APPLID) END-EXEC MOVE EIBTASKN TO ABND-TASKNO-KEY MOVE EIBTRNID TO ABND-TRANID PERFORM POPULATE-TIME-DATE MOVE WS-ORIG-DATE TO ABND-DATE STRING WS-TIME-NOW-GRP-HH DELIMITED BY SIZE, ':' DELIMITED BY SIZE, WS-TIME-NOW-GRP-MM DELIMITED BY SIZE, ':' DELIMITED BY SIZE, WS-TIME-NOW-GRP-MM DELIMITED BY SIZE INTO ABND-TIME END-STRING MOVE WS-U-TIME TO ABND-UTIME-KEY MOVE 'RUF2' TO ABND-CODE EXEC CICS ASSIGN PROGRAM(ABND-PROGRAM) END-EXEC MOVE ZEROS TO ABND-SQLCODE IF SQLERRD(3) = 13172872 STRING 'UAD010-TO(5) - timeout detected ' DELIMITED BY SIZE, ' EIBRESP=' DELIMITED BY SIZE, ABND-RESPCODE DELIMITED BY SIZE, ' RESP2=' DELIMITED BY SIZE, ABND-RESP2CODE DELIMITED BY SIZE INTO ABND-FREEFORM END-STRING END-IF EXEC CICS LINK PROGRAM(WS-ABEND-PGM) COMMAREA(ABNDINFO-REC) | G51: Decisão | H51: IF | I51: comentário curto; trecho truncado (30 linhas) | L51: A validar
A52: XFRFUN-061 | B52: XFRFUN | C52: 1644 | D52: 1646-1648 | E52: Check the SQLCODE | F52: IF SQLCODE NOT = 0 MOVE SQLCODE TO WS-SQLCODE-DISP | G52: Decisão e falha | H52: IF, falha | I52: comentário curto | L52: A validar
A53: XFRFUN-062 | B53: XFRFUN | C53: 1650-1653 | D53: 1655-1657 | E53: Preserve the RESP and RESP2, then set up the standard ABEND info before getting the applid, date/time etc. and linking to the Abend Handler program. | F53: INITIALIZE ABNDINFO-REC MOVE EIBRESP TO ABND-RESPCODE MOVE EIBRESP2 TO ABND-RESP2CODE | G53: Falha | H53: falha | L53: A validar
A54: XFRFUN-064 | B54: XFRFUN | C54: 1711-1712 | D54: 1714-1738 | E54: Check if SQLCODE indicates that Storm Drain processing is applicable in a workload if activated | F54: PERFORM CHECK-FOR-STORM-DRAIN-DB2 EXEC CICS ABEND ABCODE('WPCD') END-EXEC END-IF. WTPD999. EXIT. GET-ME-OUT-OF-HERE SECTION. GMOOH010. EXEC CICS RETURN END-EXEC. GOBACK. GMOOH999. EXIT. CHECK-FOR-STORM-DRAIN-DB2 SECTION. CFSDD010. | G54: Falha | H54: falha | L54: A validar
A55: XFRFUN-065 | B55: XFRFUN | C55: 1741-1742 | D55: 1744-1770 | E55: Check if the Sqlcode that is returned one that will trigger Storm Drain is active in Workload | F55: EVALUATE SQLCODE WHEN 923 MOVE 'DB2 Connection lost ' TO STORM-DRAIN-CONDITION WHEN OTHER MOVE 'Not Storm Drain ' TO STORM-DRAIN-CONDITION END-EVALUATE. IF STORM-DRAIN-CONDITION NOT EQUAL 'Not Storm Drain ' DISPLAY 'XFRFUN: Check-For-Storm-Drain-DB2: Storm ' 'Drain condition (' STORM-DRAIN-CONDITION ') ' 'has been met (' SQLCODE-DISPLAY ').' ELSE CONTINUE END-IF. CFSDD999. EXIT. ABEND-HANDLING SECTION. AH010. | G55: Decisão e falha | H55: IF, EVALUATE, WHEN, falha | L55: A validar
...

Sheet Descartados
A1: ID | B1: Programa | C1: Linhas do comentário | D1: Linhas do código | E1: Comentário | F1: Trecho de código | G1: Motivo do descarte | H1: Alertas | I1: Reavaliação
A2: DBCRFUN-002 | B2: DBCRFUN | C2: 215-221 | D2: 223 | E2: Determine what kind of ACCOUNT datastore we should be accessing Go and update the ACCOUNT record | F2: PERFORM UPDATE-ACCOUNT-DB2. | G2: Procedural (sem decisão nem tratamento de falha) | H2: comentário menciona condição: reavaliar
A3: DBCRFUN-003 | B3: DBCRFUN | C3: 225-226 | D3: 229-240 | E3: The COMMAREA values have now been set so all we need to do is finish | F3: PERFORM GET-ME-OUT-OF-HERE. A999. EXIT. UPDATE-ACCOUNT-DB2 SECTION. UAD010. MOVE COMM-ACCNO TO DESIRED-ACC-NO. MOVE DESIRED-SORT-CODE TO HV-ACCOUNT-SORTCODE. MOVE DESIRED-ACC-NO TO HV-ACCOUNT-ACC-NO. | G3: Procedural (sem decisão nem tratamento de falha)
A4: DBCRFUN-004 | B4: DBCRFUN | C4: 243 | D4: 245-273 | E4: Retrieve the account information | F4: EXEC SQL SELECT ACCOUNT_EYECATCHER, ACCOUNT_CUSTOMER_NUMBER, ACCOUNT_SORTCODE, ACCOUNT_NUMBER, ACCOUNT_TYPE, ACCOUNT_INTEREST_RATE, ACCOUNT_OPENED, ACCOUNT_OVERDRAFT_LIMIT, ACCOUNT_LAST_STATEMENT, ACCOUNT_NEXT_STATEMENT, ACCOUNT_AVAILABLE_BALANCE, ACCOUNT_ACTUAL_BALANCE INTO :HV-ACCOUNT-EYECATCHER, :HV-ACCOUNT-CUST-NO, :HV-ACCOUNT-SORTCODE, :HV-ACCOUNT-ACC-NO, :HV-ACCOUNT-ACC-TYPE, :HV-ACCOUNT-INT-RATE, :HV-ACCOUNT-OPENED, :HV-ACCOUNT-OVERDRAFT-LIM, :HV-ACCOUNT-LAST-STMT, :HV-ACCOUNT-NEXT-STMT, :HV-ACCOUNT-AVAIL-BAL, :HV-ACCOUNT-ACTUAL-BAL FROM ACCOUNT WHERE (ACCOUNT_SORTCODE = :HV-ACCOUNT-SORTCODE AND ACCOUNT_NUMBER = :HV-ACCOUNT-ACC-NO) END-EXEC. | G4: Procedural (sem decisão nem tratamento de falha)
A5: DBCRFUN-006 | B5: DBCRFUN | C5: 290-291 | D5: 293-297 | E5: Check if SQLCODE indicates that Storm Drain processing is applicable in a workload if activated | F5: PERFORM CHECK-FOR-STORM-DRAIN-DB2 GO TO UAD999 END-IF. | G5: Procedural (sem decisão nem tratamento de falha) | H5: comentário menciona condição: reavaliar
A6: DBCRFUN-010 | B6: DBCRFUN | C6: 380-382 | D6: 384-387 | E6: If the SQLCODE from the SELECT is OK then update the record and update the details on the PROCTRAN (Processed transaction) datastore. | F6: COMPUTE HV-ACCOUNT-AVAIL-BAL = HV-ACCOUNT-AVAIL-BAL + COMM-AMT. COMPUTE HV-ACCOUNT-ACTUAL-BAL = HV-ACCOUNT-ACTUAL-BAL + COMM-AMT. | G6: Procedural (sem decisão nem tratamento de falha) | H6: comentário menciona condição: reavaliar
A7: DBCRFUN-011 | B7: DBCRFUN | C7: 390 | D7: 392-408 | E7: Update the account record | F7: EXEC SQL UPDATE ACCOUNT SET ACCOUNT_EYECATCHER = :HV-ACCOUNT-EYECATCHER, ACCOUNT_CUSTOMER_NUMBER = :HV-ACCOUNT-CUST-NO, ACCOUNT_SORTCODE = :HV-ACCOUNT-SORTCODE, ACCOUNT_NUMBER = :HV-ACCOUNT-ACC-NO, ACCOUNT_TYPE = :HV-ACCOUNT-ACC-TYPE, ACCOUNT_INTEREST_RATE = :HV-ACCOUNT-INT-RATE, ACCOUNT_OPENED = :HV-ACCOUNT-OPENED, ACCOUNT_OVERDRAFT_LIMIT = :HV-ACCOUNT-OVERDRAFT-LIM, ACCOUNT_LAST_STATEMENT = :HV-ACCOUNT-LAST-STMT, ACCOUNT_NEXT_STATEMENT = :HV-ACCOUNT-NEXT-STMT, ACCOUNT_AVAILABLE_BALANCE = :HV-ACCOUNT-AVAIL-BAL, ACCOUNT_ACTUAL_BALANCE = :HV-ACCOUNT-ACTUAL-BAL WHERE (ACCOUNT_SORTCODE = :HV-ACCOUNT-SORTCODE AND ACCOUNT_NUMBER = :HV-ACCOUNT-ACC-NO) END-EXEC. | G7: Procedural (sem decisão nem tratamento de falha)
A8: DBCRFUN-014 | B8: DBCRFUN | C8: 429-430 | D8: 432-435 | E8: Check if SQLCODE indicates that Storm Drain processing is applicable in a workload if activated | F8: PERFORM CHECK-FOR-STORM-DRAIN-DB2 GO TO UAD999 END-IF. | G8: Procedural (sem decisão nem tratamento de falha) | H8: comentário menciona condição: reavaliar
A9: DBCRFUN-015 | B9: DBCRFUN | C9: 438-439 | D9: 441-448 | E9: If the RESP CODE was normal then we need to write to the PROCTRAN (processed transaction) datastore. | F9: PERFORM WRITE-TO-PROCTRAN. UAD999. EXIT. WRITE-TO-PROCTRAN SECTION. WTP010. | G9: Procedural (sem decisão nem tratamento de falha) | H9: comentário menciona condição: reavaliar
A10: DBCRFUN-016 | B10: DBCRFUN | C10: 451-452 | D10: 454-470 | E10: Write to the PROCTRAN datastore deatils regarding the successfully applied transaction. | F10: PERFORM WRITE-TO-PROCTRAN-DB2. WTP999. EXIT. WRITE-TO-PROCTRAN-DB2 SECTION. WTPD010. INITIALIZE HOST-PROCTRAN-ROW. INITIALIZE WS-EIBTASKN12. MOVE 'PRTR' TO HV-PROCTRAN-EYECATCHER. MOVE COMM-SORTC TO HV-PROCTRAN-SORT-CODE. MOVE COMM-ACCNO TO HV-PROCTRAN-ACC-NUMBER. MOVE EIBTASKN TO WS-EIBTASKN12. MOVE WS-EIBTASKN12 TO HV-PROCTRAN-REF. | G10: Procedural (sem decisão nem tratamento de falha)
A11: DBCRFUN-020 | B11: DBCRFUN | C11: 522 | D11: 524-549 | E11: Write a record to PROCTRAN | F11: EXEC SQL INSERT INTO PROCTRAN ( PROCTRAN_EYECATCHER, PROCTRAN_SORTCODE, PROCTRAN_NUMBER, PROCTRAN_DATE, PROCTRAN_TIME, PROCTRAN_REF, PROCTRAN_TYPE, PROCTRAN_DESC, PROCTRAN_AMOUNT ) VALUES ( :HV-PROCTRAN-EYECATCHER, :HV-PROCTRAN-SORT-CODE, :HV-PROCTRAN-ACC-NUMBER, :HV-PROCTRAN-DATE, :HV-PROCTRAN-TIME, :HV-PROCTRAN-REF, :HV-PROCTRAN-TYPE, :HV-PROCTRAN-DESC, :HV-PROCTRAN-AMOUNT ) END-EXEC. | G11: Procedural (sem decisão nem tratamento de falha)
A12: DBCRFUN-024 | B12: DBCRFUN | C12: 580 | D12: 582-618 | E12: Get supplemental information | F12: EXEC CICS ASSIGN APPLID(ABND-APPLID) END-EXEC MOVE EIBTASKN TO ABND-TASKNO-KEY MOVE EIBTRNID TO ABND-TRANID PERFORM POPULATE-TIME-DATE MOVE WS-ORIG-DATE TO ABND-DATE STRING WS-TIME-NOW-GRP-HH DELIMITED BY SIZE, ':' DELIMITED BY SIZE, WS-TIME-NOW-GRP-MM DELIMITED BY SIZE, ':' DELIMITED BY SIZE, WS-TIME-NOW-GRP-MM DELIMITED BY SIZE INTO ABND-TIME END-STRING MOVE WS-U-TIME TO ABND-UTIME-KEY MOVE 'HROL' TO ABND-CODE EXEC CICS ASSIGN PROGRAM(ABND-PROGRAM) END-EXEC MOVE ZEROS TO ABND-SQLCODE STRING 'WTPD010 - COULD NOT ROLL BACK, POSSIBLE DATA' DELIMITED BY SIZE, 'INTEGRITY ISSUE BETWEEN ACCOUNT AND PROCTRAN ' DELIMITED BY SIZE, 'FOR ROW:' DELIMITED BY SIZE, HOST-PROCTRAN-ROW DELIMITED BY SIZE, 'EIBRESP=' DELIMITED BY SIZE, ABND-RESPCODE DELIMITED BY SIZE, ' RESP2=' DELIMITED BY SIZE, ABND-RESP2CODE DELIMITED BY SIZE INTO ABND-FREEFORM END-STRING | G12: Procedural (sem decisão nem tratamento de falha) | H12: comentário curto; trecho truncado (30 linhas)
A13: DBCRFUN-025 | B13: DBCRFUN | C13: 639-640 | D13: 642-644 | E13: Check if SQLCODE indicates that Storm Drain processing is applicable in a workload if activated | F13: PERFORM CHECK-FOR-STORM-DRAIN-DB2 ELSE | G13: Procedural (sem decisão nem tratamento de falha) | H13: comentário menciona condição: reavaliar
A14: DBCRFUN-026 | B14: DBCRFUN | C14: 647 | D14: 649-669 | E14: If the WRITE to PROCTRAN worked then it was a success | F14: MOVE 'Y' TO COMM-SUCCESS MOVE '0' TO COMM-FAIL-CODE END-IF. WTPD999. EXIT. GET-ME-OUT-OF-HERE SECTION. GMOOH010. EXEC CICS RETURN END-EXEC. GOBACK. GMOOH999. EXIT. CHECK-FOR-STORM-DRAIN-DB2 SECTION. CFSDD010. | G14: Procedural (sem decisão nem tratamento de falha) | H14: comentário menciona condição: reavaliar
A15: DBCRFUN-028 | B15: DBCRFUN | C15: 699 | D15: 701-705 | E15: How ABENDs are dealt with | F15: ABEND-HANDLING SECTION. AH010. EXEC CICS ASSIGN ABCODE(MY-ABEND-CODE) END-EXEC. | G15: Procedural (sem decisão nem tratamento de falha)
A16: DBCRFUN-033 | B16: DBCRFUN | C16: 767 | D16: 769-805 | E16: Get supplemental information | F16: EXEC CICS ASSIGN APPLID(ABND-APPLID) END-EXEC MOVE EIBTASKN TO ABND-TASKNO-KEY MOVE EIBTRNID TO ABND-TRANID PERFORM POPULATE-TIME-DATE MOVE WS-ORIG-DATE TO ABND-DATE STRING WS-TIME-NOW-GRP-HH DELIMITED BY SIZE, ':' DELIMITED BY SIZE, WS-TIME-NOW-GRP-MM DELIMITED BY SIZE, ':' DELIMITED BY SIZE, WS-TIME-NOW-GRP-MM DELIMITED BY SIZE INTO ABND-TIME END-STRING MOVE WS-U-TIME TO ABND-UTIME-KEY MOVE 'HROL' TO ABND-CODE EXEC CICS ASSIGN PROGRAM(ABND-PROGRAM) END-EXEC MOVE ZEROS TO ABND-SQLCODE STRING 'AH010 - Unable to perform Synpoint ' DELIMITED BY SIZE, 'Rollback.' DELIMITED BY SIZE, ' Possible Integrity issue following VSAM RLS ' DELIMITED BY SIZE, 'abend.' DELIMITED BY SIZE, 'EIBRESP=' DELIMITED BY SIZE, ABND-RESPCODE DELIMITED BY SIZE, ' RESP2=' DELIMITED BY SIZE, ABND-RESP2CODE DELIMITED BY SIZE INTO ABND-FREEFORM END-STRING | G16: Procedural (sem decisão nem tratamento de falha) | H16: comentário curto; trecho truncado (30 linhas)
A17: XFRFUN-002 | B17: XFRFUN | C17: 299-300 | D17: 302-311 | E17: The COMMAREA values have now been set so all we need to do is finish | F17: PERFORM GET-ME-OUT-OF-HERE. A999. EXIT. UPDATE-ACCOUNT-DB2 SECTION. UAD010. MOVE 'N' TO COMM-SUCCESS. | G17: Procedural (sem decisão nem tratamento de falha)
A18: XFRFUN-005 | B18: XFRFUN | C18: 328 | D18: 330-368 | E18: Get supplemental information | F18: EXEC CICS ASSIGN APPLID(ABND-APPLID) END-EXEC MOVE EIBTASKN TO ABND-TASKNO-KEY MOVE EIBTRNID TO ABND-TRANID PERFORM POPULATE-TIME-DATE MOVE WS-ORIG-DATE TO ABND-DATE STRING WS-TIME-NOW-GRP-HH DELIMITED BY SIZE, ':' DELIMITED BY SIZE, WS-TIME-NOW-GRP-MM DELIMITED BY SIZE, ':' DELIMITED BY SIZE, WS-TIME-NOW-GRP-MM DELIMITED BY SIZE INTO ABND-TIME END-STRING MOVE WS-U-TIME TO ABND-UTIME-KEY MOVE 'SAME' TO ABND-CODE EXEC CICS ASSIGN PROGRAM(ABND-PROGRAM) END-EXEC MOVE ZEROS TO ABND-SQLCODE STRING 'UAD010 - Cannot transfer to the same account ' DELIMITED BY SIZE, ' EIBRESP=' DELIMITED BY SIZE, ABND-RESPCODE DELIMITED BY SIZE, ' RESP2=' DELIMITED BY SIZE, ABND-RESP2CODE DELIMITED BY SIZE INTO ABND-FREEFORM END-STRING EXEC CICS LINK PROGRAM(WS-ABEND-PGM) COMMAREA(ABNDINFO-REC) END-EXEC DISPLAY 'Cannot transfer to the same account' | G18: Procedural (sem decisão nem tratamento de falha) | H18: comentário curto; trecho truncado (30 linhas)
A19: XFRFUN-006 | B19: XFRFUN | C19: 380-381 | D19: 383-384 | E19: If the FROM account number is less than the TO account number | F19: MOVE COMM-FACCNO TO DESIRED-ACC-NO MOVE COMM-FSCODE TO DESIRED-SORT-CODE | G19: Procedural (sem decisão nem tratamento de falha) | H19: comentário menciona condição: reavaliar
A20: XFRFUN-007 | B20: XFRFUN | C20: 387 | D20: 389 | E20: Update the FROM account | F20: PERFORM UPDATE-ACCOUNT-DB2-FROM | G20: Procedural (sem decisão nem tratamento de falha)
A21: XFRFUN-011 | B21: XFRFUN | C21: 424 | D21: 426-463 | E21: Get supplemental information | F21: EXEC CICS ASSIGN APPLID(ABND-APPLID) END-EXEC MOVE EIBTASKN TO ABND-TASKNO-KEY MOVE EIBTRNID TO ABND-TRANID PERFORM POPULATE-TIME-DATE MOVE WS-ORIG-DATE TO ABND-DATE STRING WS-TIME-NOW-GRP-HH DELIMITED BY SIZE, ':' DELIMITED BY SIZE, WS-TIME-NOW-GRP-MM DELIMITED BY SIZE, ':' DELIMITED BY SIZE, WS-TIME-NOW-GRP-MM DELIMITED BY SIZE INTO ABND-TIME END-STRING MOVE WS-U-TIME TO ABND-UTIME-KEY MOVE 'HROL' TO ABND-CODE EXEC CICS ASSIGN PROGRAM(ABND-PROGRAM) END-EXEC MOVE ZEROS TO ABND-SQLCODE STRING 'UAD010(2) - Error on SYNCPOINT' DELIMITED BY SIZE, ' ROLLBACK' DELIMITED BY SIZE, ' after UPDATING TO account ' DELIMITED BY SIZE, ' EIBRESP=' DELIMITED BY SIZE, ABND-RESPCODE DELIMITED BY SIZE, ' RESP2=' DELIMITED BY SIZE, ABND-RESP2CODE DELIMITED BY SIZE INTO ABND-FREEFORM END-STRING EXEC CICS LINK PROGRAM(WS-ABEND-PGM) | G21: Procedural (sem decisão nem tratamento de falha) | H21: comentário curto; trecho truncado (30 linhas)
A22: XFRFUN-016 | B22: XFRFUN | C22: 537 | D22: 539-577 | E22: Get supplemental information | F22: EXEC CICS ASSIGN APPLID(ABND-APPLID) END-EXEC MOVE EIBTASKN TO ABND-TASKNO-KEY MOVE EIBTRNID TO ABND-TRANID PERFORM POPULATE-TIME-DATE MOVE WS-ORIG-DATE TO ABND-DATE STRING WS-TIME-NOW-GRP-HH DELIMITED BY SIZE, ':' DELIMITED BY SIZE, WS-TIME-NOW-GRP-MM DELIMITED BY SIZE, ':' DELIMITED BY SIZE, WS-TIME-NOW-GRP-MM DELIMITED BY SIZE INTO ABND-TIME END-STRING MOVE WS-U-TIME TO ABND-UTIME-KEY MOVE 'FROM' TO ABND-CODE EXEC CICS ASSIGN PROGRAM(ABND-PROGRAM) END-EXEC MOVE ZEROS TO ABND-SQLCODE STRING 'UAD010(3) - Error updating FROM account ' DELIMITED BY SIZE, ' EIBRESP=' DELIMITED BY SIZE, ABND-RESPCODE DELIMITED BY SIZE, ' RESP2=' DELIMITED BY SIZE, ABND-RESP2CODE DELIMITED BY SIZE INTO ABND-FREEFORM END-STRING EXEC CICS LINK PROGRAM(WS-ABEND-PGM) COMMAREA(ABNDINFO-REC) END-EXEC DISPLAY 'Error updating FROM account' | G22: Procedural (sem decisão nem tratamento de falha) | H22: comentário curto; trecho truncado (30 linhas)
A23: XFRFUN-017 | B23: XFRFUN | C23: 591-592 | D23: 594-595 | E23: The FROM account number is greater than the TO account number | F23: MOVE COMM-TACCNO TO DESIRED-ACC-NO MOVE COMM-TSCODE TO DESIRED-SORT-CODE | G23: Procedural (sem decisão nem tratamento de falha)
A24: XFRFUN-018 | B24: XFRFUN | C24: 598 | D24: 600 | E24: Update the TO account number | F24: PERFORM UPDATE-ACCOUNT-DB2-TO | G24: Procedural (sem decisão nem tratamento de falha)
A25: XFRFUN-022 | B25: XFRFUN | C25: 628 | D25: 630-668 | E25: Get supplemental information | F25: EXEC CICS ASSIGN APPLID(ABND-APPLID) END-EXEC MOVE EIBTASKN TO ABND-TASKNO-KEY MOVE EIBTRNID TO ABND-TRANID PERFORM POPULATE-TIME-DATE MOVE WS-ORIG-DATE TO ABND-DATE STRING WS-TIME-NOW-GRP-HH DELIMITED BY SIZE, ':' DELIMITED BY SIZE, WS-TIME-NOW-GRP-MM DELIMITED BY SIZE, ':' DELIMITED BY SIZE, WS-TIME-NOW-GRP-MM DELIMITED BY SIZE INTO ABND-TIME END-STRING MOVE WS-U-TIME TO ABND-UTIME-KEY MOVE 'FROM' TO ABND-CODE EXEC CICS ASSIGN PROGRAM(ABND-PROGRAM) END-EXEC MOVE ZEROS TO ABND-SQLCODE STRING 'UAD010(4) - Error updating FROM account ' DELIMITED BY SIZE, ' EIBRESP=' DELIMITED BY SIZE, ABND-RESPCODE DELIMITED BY SIZE, ' RESP2=' DELIMITED BY SIZE, ABND-RESP2CODE DELIMITED BY SIZE INTO ABND-FREEFORM END-STRING EXEC CICS LINK PROGRAM(WS-ABEND-PGM) COMMAREA(ABNDINFO-REC) END-EXEC DISPLAY 'Error updating FROM account' | G25: Procedural (sem decisão nem tratamento de falha) | H25: comentário curto; trecho truncado (30 linhas)
A26: XFRFUN-023 | B26: XFRFUN | C26: 677 | D26: 679-683 | E26: If the FAIL code is something else | F26: EXEC CICS SYNCPOINT ROLLBACK RESP(WS-CICS-RESP) RESP2(WS-CICS-RESP2) END-EXEC | G26: Procedural (sem decisão nem tratamento de falha) | H26: comentário menciona condição: reavaliar
A27: XFRFUN-026 | B27: XFRFUN | C27: 698 | D27: 700-737 | E27: Get supplemental information | F27: EXEC CICS ASSIGN APPLID(ABND-APPLID) END-EXEC MOVE EIBTASKN TO ABND-TASKNO-KEY MOVE EIBTRNID TO ABND-TRANID PERFORM POPULATE-TIME-DATE MOVE WS-ORIG-DATE TO ABND-DATE STRING WS-TIME-NOW-GRP-HH DELIMITED BY SIZE, ':' DELIMITED BY SIZE, WS-TIME-NOW-GRP-MM DELIMITED BY SIZE, ':' DELIMITED BY SIZE, WS-TIME-NOW-GRP-MM DELIMITED BY SIZE INTO ABND-TIME END-STRING MOVE WS-U-TIME TO ABND-UTIME-KEY MOVE 'HROL' TO ABND-CODE EXEC CICS ASSIGN PROGRAM(ABND-PROGRAM) END-EXEC MOVE ZEROS TO ABND-SQLCODE STRING 'UAD010(5) - Error on SYNCPOINT ' DELIMITED BY SIZE, ' ROLLBACK ' DELIMITED BY SIZE, ' after UPDATING the FROM account' DELIMITED BY SIZE, ' EIBRESP=' DELIMITED BY SIZE, ABND-RESPCODE DELIMITED BY SIZE, ' RESP2=' DELIMITED BY SIZE, ABND-RESP2CODE DELIMITED BY SIZE INTO ABND-FREEFORM END-STRING EXEC CICS LINK PROGRAM(WS-ABEND-PGM) | G27: Procedural (sem decisão nem tratamento de falha) | H27: comentário curto; trecho truncado (30 linhas)
A28: XFRFUN-029 | B28: XFRFUN | C28: 777 | D28: 779-817 | E28: Get supplemental information | F28: EXEC CICS ASSIGN APPLID(ABND-APPLID) END-EXEC MOVE EIBTASKN TO ABND-TASKNO-KEY MOVE EIBTRNID TO ABND-TRANID PERFORM POPULATE-TIME-DATE MOVE WS-ORIG-DATE TO ABND-DATE STRING WS-TIME-NOW-GRP-HH DELIMITED BY SIZE, ':' DELIMITED BY SIZE, WS-TIME-NOW-GRP-MM DELIMITED BY SIZE, ':' DELIMITED BY SIZE, WS-TIME-NOW-GRP-MM DELIMITED BY SIZE INTO ABND-TIME END-STRING MOVE WS-U-TIME TO ABND-UTIME-KEY MOVE 'TO ' TO ABND-CODE EXEC CICS ASSIGN PROGRAM(ABND-PROGRAM) END-EXEC MOVE ZEROS TO ABND-SQLCODE STRING 'UAD010(6) - Error updating TO account ' DELIMITED BY SIZE, ' EIBRESP=' DELIMITED BY SIZE, ABND-RESPCODE DELIMITED BY SIZE, ' RESP2=' DELIMITED BY SIZE, ABND-RESP2CODE DELIMITED BY SIZE INTO ABND-FREEFORM END-STRING EXEC CICS LINK PROGRAM(WS-ABEND-PGM) COMMAREA(ABNDINFO-REC) END-EXEC DISPLAY 'Error updating TO account' | G28: Procedural (sem decisão nem tratamento de falha) | H28: comentário curto; trecho truncado (30 linhas)
A29: XFRFUN-031 | B29: XFRFUN | C29: 843 | D29: 845-882 | E29: Get supplemental information | F29: EXEC CICS ASSIGN APPLID(ABND-APPLID) END-EXEC MOVE EIBTASKN TO ABND-TASKNO-KEY MOVE EIBTRNID TO ABND-TRANID PERFORM POPULATE-TIME-DATE MOVE WS-ORIG-DATE TO ABND-DATE STRING WS-TIME-NOW-GRP-HH DELIMITED BY SIZE, ':' DELIMITED BY SIZE, WS-TIME-NOW-GRP-MM DELIMITED BY SIZE, ':' DELIMITED BY SIZE, WS-TIME-NOW-GRP-MM DELIMITED BY SIZE INTO ABND-TIME END-STRING MOVE WS-U-TIME TO ABND-UTIME-KEY MOVE 'HROL' TO ABND-CODE EXEC CICS ASSIGN PROGRAM(ABND-PROGRAM) END-EXEC MOVE ZEROS TO ABND-SQLCODE STRING 'UAD010(7) - Error on SYNCPOINT ROLLBACK' DELIMITED BY SIZE, ' after UPDATING the TO account' DELIMITED BY SIZE, ' EIBRESP=' DELIMITED BY SIZE, ABND-RESPCODE DELIMITED BY SIZE, ' RESP2=' DELIMITED BY SIZE, ABND-RESP2CODE DELIMITED BY SIZE INTO ABND-FREEFORM END-STRING EXEC CICS LINK PROGRAM(WS-ABEND-PGM) COMMAREA(ABNDINFO-REC) | G29: Procedural (sem decisão nem tratamento de falha) | H29: comentário curto; trecho truncado (30 linhas)
A30: XFRFUN-032 | B30: XFRFUN | C30: 907-909 | D30: 911-920 | E30: If the updates to the TO and FROM accounts were successful then we need to write to PROCTRAN (processed transaction) to record the successful transfer. | F30: PERFORM WRITE-TO-PROCTRAN. MOVE 'Y' TO COMM-SUCCESS. UAD999. EXIT. UPDATE-ACCOUNT-DB2-FROM SECTION. UADF010. | G30: Procedural (sem decisão nem tratamento de falha) | H30: comentário menciona condição: reavaliar
A31: XFRFUN-033 | B31: XFRFUN | C31: 922 | D31: 924-955 | E31: Position ourself at the matching FROM account record | F31: MOVE COMM-FACCNO TO DESIRED-ACC-NO. MOVE COMM-FSCODE TO DESIRED-SORT-CODE. MOVE DESIRED-SORT-CODE TO HV-ACCOUNT-SORTCODE. MOVE DESIRED-ACC-NO TO HV-ACCOUNT-ACC-NO. EXEC SQL SELECT ACCOUNT_EYECATCHER, ACCOUNT_CUSTOMER_NUMBER, ACCOUNT_SORTCODE, ACCOUNT_NUMBER, ACCOUNT_TYPE, ACCOUNT_INTEREST_RATE, ACCOUNT_OPENED, ACCOUNT_OVERDRAFT_LIMIT, ACCOUNT_LAST_STATEMENT, ACCOUNT_NEXT_STATEMENT, ACCOUNT_AVAILABLE_BALANCE, ACCOUNT_ACTUAL_BALANCE INTO :HV-ACCOUNT-EYECATCHER, :HV-ACCOUNT-CUST-NO, :HV-ACCOUNT-SORTCODE, :HV-ACCOUNT-ACC-NO, :HV-ACCOUNT-ACC-TYPE, :HV-ACCOUNT-INT-RATE, :HV-ACCOUNT-OPENED, :HV-ACCOUNT-OVERDRAFT-LIM, :HV-ACCOUNT-LAST-STMT, :HV-ACCOUNT-NEXT-STMT, :HV-ACCOUNT-AVAIL-BAL, :HV-ACCOUNT-ACTUAL-BAL FROM ACCOUNT | G31: Procedural (sem decisão nem tratamento de falha) | H31: trecho truncado (30 linhas)
A32: XFRFUN-035 | B32: XFRFUN | C32: 973-974 | D32: 976-980 | E32: Check if SQLCODE indicates that Storm Drain processing is applicable in a workload if activated | F32: PERFORM CHECK-FOR-STORM-DRAIN-DB2 GO TO UADF999 END-IF. | G32: Procedural (sem decisão nem tratamento de falha) | H32: comentário menciona condição: reavaliar
A33: XFRFUN-036 | B33: XFRFUN | C33: 983-984 | D33: 986-1008 | E33: If the SQLCODE is OK then update the row on ACCOUNT for the FROM account. | F33: COMPUTE HV-ACCOUNT-AVAIL-BAL = HV-ACCOUNT-AVAIL-BAL - COMM-AMT. COMPUTE HV-ACCOUNT-ACTUAL-BAL = HV-ACCOUNT-ACTUAL-BAL - COMM-AMT. EXEC SQL UPDATE ACCOUNT SET ACCOUNT_EYECATCHER = :HV-ACCOUNT-EYECATCHER, ACCOUNT_CUSTOMER_NUMBER = :HV-ACCOUNT-CUST-NO, ACCOUNT_SORTCODE = :HV-ACCOUNT-SORTCODE, ACCOUNT_NUMBER = :HV-ACCOUNT-ACC-NO, ACCOUNT_TYPE = :HV-ACCOUNT-ACC-TYPE, ACCOUNT_INTEREST_RATE = :HV-ACCOUNT-INT-RATE, ACCOUNT_OPENED = :HV-ACCOUNT-OPENED, ACCOUNT_OVERDRAFT_LIMIT = :HV-ACCOUNT-OVERDRAFT-LIM, ACCOUNT_LAST_STATEMENT = :HV-ACCOUNT-LAST-STMT, ACCOUNT_NEXT_STATEMENT = :HV-ACCOUNT-NEXT-STMT, ACCOUNT_AVAILABLE_BALANCE = :HV-ACCOUNT-AVAIL-BAL, ACCOUNT_ACTUAL_BALANCE = :HV-ACCOUNT-ACTUAL-BAL WHERE (ACCOUNT_SORTCODE = :HV-ACCOUNT-SORTCODE AND ACCOUNT_NUMBER = :HV-ACCOUNT-ACC-NO) END-EXEC. | G33: Procedural (sem decisão nem tratamento de falha) | H33: comentário menciona condição: reavaliar
A34: XFRFUN-038 | B34: XFRFUN | C34: 1020-1021 | D34: 1023-1027 | E34: Check if SQLCODE indicates that Storm Drain processing is applicable in a workload if activated | F34: PERFORM CHECK-FOR-STORM-DRAIN-DB2 GO TO UADF999 END-IF. | G34: Procedural (sem decisão nem tratamento de falha) | H34: comentário menciona condição: reavaliar
A35: XFRFUN-039 | B35: XFRFUN | C35: 1030-1031 | D35: 1033-1044 | E35: If the update to the FROM account was OK store the updated balances away. | F35: MOVE HV-ACCOUNT-AVAIL-BAL TO COMM-FAVBAL. MOVE HV-ACCOUNT-ACTUAL-BAL TO COMM-FACTBAL. MOVE 'Y' TO COMM-SUCCESS. UADF999. EXIT. UPDATE-ACCOUNT-DB2-TO SECTION. UADT010. MOVE 'N' TO COMM-SUCCESS. | G35: Procedural (sem decisão nem tratamento de falha) | H35: comentário menciona condição: reavaliar
A36: XFRFUN-040 | B36: XFRFUN | C36: 1046-1047 | D36: 1049-1081 | E36: Position ourself at the matching account record for the TO account | F36: INITIALIZE HOST-ACCOUNT-ROW. MOVE COMM-TACCNO TO DESIRED-ACC-NO. MOVE COMM-TSCODE TO DESIRED-SORT-CODE. MOVE DESIRED-SORT-CODE TO HV-ACCOUNT-SORTCODE. MOVE DESIRED-ACC-NO TO HV-ACCOUNT-ACC-NO. EXEC SQL SELECT ACCOUNT_EYECATCHER, ACCOUNT_CUSTOMER_NUMBER, ACCOUNT_SORTCODE, ACCOUNT_NUMBER, ACCOUNT_TYPE, ACCOUNT_INTEREST_RATE, ACCOUNT_OPENED, ACCOUNT_OVERDRAFT_LIMIT, ACCOUNT_LAST_STATEMENT, ACCOUNT_NEXT_STATEMENT, ACCOUNT_AVAILABLE_BALANCE, ACCOUNT_ACTUAL_BALANCE INTO :HV-ACCOUNT-EYECATCHER, :HV-ACCOUNT-CUST-NO, :HV-ACCOUNT-SORTCODE, :HV-ACCOUNT-ACC-NO, :HV-ACCOUNT-ACC-TYPE, :HV-ACCOUNT-INT-RATE, :HV-ACCOUNT-OPENED, :HV-ACCOUNT-OVERDRAFT-LIM, :HV-ACCOUNT-LAST-STMT, :HV-ACCOUNT-NEXT-STMT, :HV-ACCOUNT-AVAIL-BAL, :HV-ACCOUNT-ACTUAL-BAL | G36: Procedural (sem decisão nem tratamento de falha) | H36: trecho truncado (30 linhas)
... A41: XFRFUN-055 | B41: XFRFUN | C41: 1421 | D41: 1423-1460 | E41: Get supplemental information | F41: EXEC CICS ASSIGN APPLID(ABND-APPLID) END-EXEC MOVE EIBTASKN TO ABND-TASKNO-KEY MOVE EIBTRNID TO ABND-TRANID PERFORM POPULATE-TIME-DATE MOVE WS-ORIG-DATE TO ABND-DATE STRING WS-TIME-NOW-GRP-HH DELIMITED BY SIZE, ':' DELIMITED BY SIZE, WS-TIME-NOW-GRP-MM DELIMITED BY SIZE, ':' DELIMITED BY SIZE, WS-TIME-NOW-GRP-MM DELIMITED BY SIZE INTO ABND-TIME END-STRING MOVE WS-U-TIME TO ABND-UTIME-KEY MOVE 'HROL' TO ABND-CODE EXEC CICS ASSIGN PROGRAM(ABND-PROGRAM) END-EXEC MOVE ZEROS TO ABND-SQLCODE STRING 'UAD010-TO(4) - Error on SYNCPOINT ' DELIMITED BY SIZE, 'ROLLBACK after Updating TO account' DELIMITED BY SIZE, ' EIBRESP=' DELIMITED BY SIZE, ABND-RESPCODE DELIMITED BY SIZE, ' RESP2=' DELIMITED BY SIZE, ABND-RESP2CODE DELIMITED BY SIZE INTO ABND-FREEFORM END-STRING EXEC CICS LINK PROGRAM(WS-ABEND-PGM) COMMAREA(ABNDINFO-REC) | G41: Procedural (sem decisão nem tratamento de falha) | H41: comentário curto; trecho truncado (30 linhas)
A42: XFRFUN-058 | B42: XFRFUN | C42: 1552 | D42: 1554-1572 | E42: Store the data away | F42: MOVE HV-ACCOUNT-AVAIL-BAL TO COMM-TAVBAL. MOVE HV-ACCOUNT-ACTUAL-BAL TO COMM-TACTBAL. MOVE 'Y' TO COMM-SUCCESS. UADT999. EXIT. WRITE-TO-PROCTRAN SECTION. WTP010. PERFORM WRITE-TO-PROCTRAN-DB2. WTP999. EXIT. WRITE-TO-PROCTRAN-DB2 SECTION. WTPD010. | G42: Procedural (sem decisão nem tratamento de falha)
A43: XFRFUN-059 | B43: XFRFUN | C43: 1574-1575 | D43: 1577-1584 | E43: Writes details of the successful transfer to the PROCTRAN (Processed Transaction) datastore. | F43: INITIALIZE HOST-PROCTRAN-ROW. INITIALIZE WS-EIBTASKN12. MOVE 'PRTR' TO HV-PROCTRAN-EYECATCHER. MOVE COMM-FSCODE TO HV-PROCTRAN-SORT-CODE. MOVE COMM-FACCNO TO HV-PROCTRAN-ACC-NUMBER. MOVE EIBTASKN TO WS-EIBTASKN12. MOVE WS-EIBTASKN12 TO HV-PROCTRAN-REF. | G43: Procedural (sem decisão nem tratamento de falha)
A44: XFRFUN-060 | B44: XFRFUN | C44: 1587 | D44: 1589-1625 | E44: Populate the time and date | F44: EXEC CICS ASKTIME ABSTIME(WS-U-TIME) END-EXEC. EXEC CICS FORMATTIME ABSTIME(WS-U-TIME) DDMMYYYY(WS-ORIG-DATE) TIME(HV-PROCTRAN-TIME) DATESEP('.') END-EXEC. MOVE WS-ORIG-DATE TO WS-ORIG-DATE-GRP-X. MOVE WS-ORIG-DATE-GRP-X TO HV-PROCTRAN-DATE. SET PROC-TY-TRANSFER IN PROCTRAN-AREA TO TRUE MOVE PROC-TRAN-TYPE IN PROCTRAN-AREA TO HV-PROCTRAN-TYPE. MOVE COMM-AMT TO HV-PROCTRAN-AMOUNT. SET PROC-TRAN-DESC-XFR-FLAG IN PROCTRAN-AREA TO TRUE. MOVE COMM-TSCODE TO PROC-TRAN-DESC-XFR-SORTCODE IN PROCTRAN-AREA. MOVE COMM-TACCNO TO PROC-TRAN-DESC-XFR-ACCOUNT IN PROCTRAN-AREA. MOVE PROC-TRAN-DESC IN PROCTRAN-AREA TO HV-PROCTRAN-DESC. EXEC SQL INSERT INTO PROCTRAN ( PROCTRAN_EYECATCHER, PROCTRAN_SORTCODE, PROCTRAN_NUMBER, PROCTRAN_DATE, PROCTRAN_TIME, PROCTRAN_REF, PROCTRAN_TYPE, | G44: Procedural (sem decisão nem tratamento de falha) | H44: trecho truncado (30 linhas)
...
